INFO 2025-08-01 08:29:35,798 autoreload 25732 4904 Watching for file changes with StatReloader
WARNING 2025-08-01 08:44:26,400 log 25732 25692 Unauthorized: /auth/login/
WARNING 2025-08-01 08:45:43,846 log 25732 32744 Not Found: /favicon.ico
WARNING 2025-08-01 08:45:47,185 base 25732 15668 view's GroupViewSet raised exception during schema generation; use `getattr(self, 'swagger_fake_view', False)` to detect and short-circuit this
Traceback (most recent call last):
  File "C:\Users\nhanh\AppData\Local\Programs\Python\Python312\Lib\site-packages\django\db\models\fields\__init__.py", line 2766, in to_python
    return uuid.UUID(**{input_form: value})
           ^^^^^^^^^^^^^^^^^^^^^^^^^^^^^^^^
  File "C:\Users\nhanh\AppData\Local\Programs\Python\Python312\Lib\uuid.py", line 175, in __init__
    hex = hex.replace('urn:', '').replace('uuid:', '')
          ^^^^^^^^^^^
AttributeError: 'AnonymousUser' object has no attribute 'replace'

During handling of the above exception, another exception occurred:

Traceback (most recent call last):
  File "C:\Users\nhanh\AppData\Local\Programs\Python\Python312\Lib\site-packages\drf_yasg\inspectors\base.py", line 42, in call_view_method
    return view_method()
           ^^^^^^^^^^^^^
  File "D:\Study\DoAnNganh\PlanPal\planpalapp\planpals\views.py", line 232, in get_queryset
    return Group.objects.filter(
           ^^^^^^^^^^^^^^^^^^^^^
  File "C:\Users\nhanh\AppData\Local\Programs\Python\Python312\Lib\site-packages\django\db\models\manager.py", line 87, in manager_method
    return getattr(self.get_queryset(), name)(*args, **kwargs)
           ^^^^^^^^^^^^^^^^^^^^^^^^^^^^^^^^^^^^^^^^^^^^^^^^^^^
  File "C:\Users\nhanh\AppData\Local\Programs\Python\Python312\Lib\site-packages\django\db\models\query.py", line 1493, in filter
    return self._filter_or_exclude(False, args, kwargs)
           ^^^^^^^^^^^^^^^^^^^^^^^^^^^^^^^^^^^^^^^^^^^^
  File "C:\Users\nhanh\AppData\Local\Programs\Python\Python312\Lib\site-packages\django\db\models\query.py", line 1511, in _filter_or_exclude
    clone._filter_or_exclude_inplace(negate, args, kwargs)
  File "C:\Users\nhanh\AppData\Local\Programs\Python\Python312\Lib\site-packages\django\db\models\query.py", line 1518, in _filter_or_exclude_inplace
    self._query.add_q(Q(*args, **kwargs))
  File "C:\Users\nhanh\AppData\Local\Programs\Python\Python312\Lib\site-packages\django\db\models\sql\query.py", line 1646, in add_q
    clause, _ = self._add_q(q_object, can_reuse)
                ^^^^^^^^^^^^^^^^^^^^^^^^^^^^^^^^
  File "C:\Users\nhanh\AppData\Local\Programs\Python\Python312\Lib\site-packages\django\db\models\sql\query.py", line 1678, in _add_q
    child_clause, needed_inner = self.build_filter(
                                 ^^^^^^^^^^^^^^^^^^
  File "C:\Users\nhanh\AppData\Local\Programs\Python\Python312\Lib\site-packages\django\db\models\sql\query.py", line 1588, in build_filter
    condition = self.build_lookup(lookups, col, value)
                ^^^^^^^^^^^^^^^^^^^^^^^^^^^^^^^^^^^^^^
  File "C:\Users\nhanh\AppData\Local\Programs\Python\Python312\Lib\site-packages\django\db\models\sql\query.py", line 1415, in build_lookup
    lookup = lookup_class(lhs, rhs)
             ^^^^^^^^^^^^^^^^^^^^^^
  File "C:\Users\nhanh\AppData\Local\Programs\Python\Python312\Lib\site-packages\django\db\models\lookups.py", line 38, in __init__
    self.rhs = self.get_prep_lookup()
               ^^^^^^^^^^^^^^^^^^^^^^
  File "C:\Users\nhanh\AppData\Local\Programs\Python\Python312\Lib\site-packages\django\db\models\fields\related_lookups.py", line 112, in get_prep_lookup
    self.rhs = target_field.get_prep_value(self.rhs)
               ^^^^^^^^^^^^^^^^^^^^^^^^^^^^^^^^^^^^^
  File "C:\Users\nhanh\AppData\Local\Programs\Python\Python312\Lib\site-packages\django\db\models\fields\__init__.py", line 2750, in get_prep_value
    return self.to_python(value)
           ^^^^^^^^^^^^^^^^^^^^^
  File "C:\Users\nhanh\AppData\Local\Programs\Python\Python312\Lib\site-packages\django\db\models\fields\__init__.py", line 2768, in to_python
    raise exceptions.ValidationError(
django.core.exceptions.ValidationError: ['“AnonymousUser” is not a valid UUID.']
WARNING 2025-08-01 08:45:47,351 base 25732 15668 view's GroupViewSet raised exception during schema generation; use `getattr(self, 'swagger_fake_view', False)` to detect and short-circuit this
Traceback (most recent call last):
  File "C:\Users\nhanh\AppData\Local\Programs\Python\Python312\Lib\site-packages\django\db\models\fields\__init__.py", line 2766, in to_python
    return uuid.UUID(**{input_form: value})
           ^^^^^^^^^^^^^^^^^^^^^^^^^^^^^^^^
  File "C:\Users\nhanh\AppData\Local\Programs\Python\Python312\Lib\uuid.py", line 175, in __init__
    hex = hex.replace('urn:', '').replace('uuid:', '')
          ^^^^^^^^^^^
AttributeError: 'AnonymousUser' object has no attribute 'replace'

During handling of the above exception, another exception occurred:

Traceback (most recent call last):
  File "C:\Users\nhanh\AppData\Local\Programs\Python\Python312\Lib\site-packages\drf_yasg\inspectors\base.py", line 42, in call_view_method
    return view_method()
           ^^^^^^^^^^^^^
  File "D:\Study\DoAnNganh\PlanPal\planpalapp\planpals\views.py", line 232, in get_queryset
    return Group.objects.filter(
           ^^^^^^^^^^^^^^^^^^^^^
  File "C:\Users\nhanh\AppData\Local\Programs\Python\Python312\Lib\site-packages\django\db\models\manager.py", line 87, in manager_method
    return getattr(self.get_queryset(), name)(*args, **kwargs)
           ^^^^^^^^^^^^^^^^^^^^^^^^^^^^^^^^^^^^^^^^^^^^^^^^^^^
  File "C:\Users\nhanh\AppData\Local\Programs\Python\Python312\Lib\site-packages\django\db\models\query.py", line 1493, in filter
    return self._filter_or_exclude(False, args, kwargs)
           ^^^^^^^^^^^^^^^^^^^^^^^^^^^^^^^^^^^^^^^^^^^^
  File "C:\Users\nhanh\AppData\Local\Programs\Python\Python312\Lib\site-packages\django\db\models\query.py", line 1511, in _filter_or_exclude
    clone._filter_or_exclude_inplace(negate, args, kwargs)
  File "C:\Users\nhanh\AppData\Local\Programs\Python\Python312\Lib\site-packages\django\db\models\query.py", line 1518, in _filter_or_exclude_inplace
    self._query.add_q(Q(*args, **kwargs))
  File "C:\Users\nhanh\AppData\Local\Programs\Python\Python312\Lib\site-packages\django\db\models\sql\query.py", line 1646, in add_q
    clause, _ = self._add_q(q_object, can_reuse)
                ^^^^^^^^^^^^^^^^^^^^^^^^^^^^^^^^
  File "C:\Users\nhanh\AppData\Local\Programs\Python\Python312\Lib\site-packages\django\db\models\sql\query.py", line 1678, in _add_q
    child_clause, needed_inner = self.build_filter(
                                 ^^^^^^^^^^^^^^^^^^
  File "C:\Users\nhanh\AppData\Local\Programs\Python\Python312\Lib\site-packages\django\db\models\sql\query.py", line 1588, in build_filter
    condition = self.build_lookup(lookups, col, value)
                ^^^^^^^^^^^^^^^^^^^^^^^^^^^^^^^^^^^^^^
  File "C:\Users\nhanh\AppData\Local\Programs\Python\Python312\Lib\site-packages\django\db\models\sql\query.py", line 1415, in build_lookup
    lookup = lookup_class(lhs, rhs)
             ^^^^^^^^^^^^^^^^^^^^^^
  File "C:\Users\nhanh\AppData\Local\Programs\Python\Python312\Lib\site-packages\django\db\models\lookups.py", line 38, in __init__
    self.rhs = self.get_prep_lookup()
               ^^^^^^^^^^^^^^^^^^^^^^
  File "C:\Users\nhanh\AppData\Local\Programs\Python\Python312\Lib\site-packages\django\db\models\fields\related_lookups.py", line 112, in get_prep_lookup
    self.rhs = target_field.get_prep_value(self.rhs)
               ^^^^^^^^^^^^^^^^^^^^^^^^^^^^^^^^^^^^^
  File "C:\Users\nhanh\AppData\Local\Programs\Python\Python312\Lib\site-packages\django\db\models\fields\__init__.py", line 2750, in get_prep_value
    return self.to_python(value)
           ^^^^^^^^^^^^^^^^^^^^^
  File "C:\Users\nhanh\AppData\Local\Programs\Python\Python312\Lib\site-packages\django\db\models\fields\__init__.py", line 2768, in to_python
    raise exceptions.ValidationError(
django.core.exceptions.ValidationError: ['“AnonymousUser” is not a valid UUID.']
WARNING 2025-08-01 08:45:47,355 base 25732 15668 view's GroupViewSet raised exception during schema generation; use `getattr(self, 'swagger_fake_view', False)` to detect and short-circuit this
Traceback (most recent call last):
  File "C:\Users\nhanh\AppData\Local\Programs\Python\Python312\Lib\site-packages\django\db\models\fields\__init__.py", line 2766, in to_python
    return uuid.UUID(**{input_form: value})
           ^^^^^^^^^^^^^^^^^^^^^^^^^^^^^^^^
  File "C:\Users\nhanh\AppData\Local\Programs\Python\Python312\Lib\uuid.py", line 175, in __init__
    hex = hex.replace('urn:', '').replace('uuid:', '')
          ^^^^^^^^^^^
AttributeError: 'AnonymousUser' object has no attribute 'replace'

During handling of the above exception, another exception occurred:

Traceback (most recent call last):
  File "C:\Users\nhanh\AppData\Local\Programs\Python\Python312\Lib\site-packages\drf_yasg\inspectors\base.py", line 42, in call_view_method
    return view_method()
           ^^^^^^^^^^^^^
  File "D:\Study\DoAnNganh\PlanPal\planpalapp\planpals\views.py", line 232, in get_queryset
    return Group.objects.filter(
           ^^^^^^^^^^^^^^^^^^^^^
  File "C:\Users\nhanh\AppData\Local\Programs\Python\Python312\Lib\site-packages\django\db\models\manager.py", line 87, in manager_method
    return getattr(self.get_queryset(), name)(*args, **kwargs)
           ^^^^^^^^^^^^^^^^^^^^^^^^^^^^^^^^^^^^^^^^^^^^^^^^^^^
  File "C:\Users\nhanh\AppData\Local\Programs\Python\Python312\Lib\site-packages\django\db\models\query.py", line 1493, in filter
    return self._filter_or_exclude(False, args, kwargs)
           ^^^^^^^^^^^^^^^^^^^^^^^^^^^^^^^^^^^^^^^^^^^^
  File "C:\Users\nhanh\AppData\Local\Programs\Python\Python312\Lib\site-packages\django\db\models\query.py", line 1511, in _filter_or_exclude
    clone._filter_or_exclude_inplace(negate, args, kwargs)
  File "C:\Users\nhanh\AppData\Local\Programs\Python\Python312\Lib\site-packages\django\db\models\query.py", line 1518, in _filter_or_exclude_inplace
    self._query.add_q(Q(*args, **kwargs))
  File "C:\Users\nhanh\AppData\Local\Programs\Python\Python312\Lib\site-packages\django\db\models\sql\query.py", line 1646, in add_q
    clause, _ = self._add_q(q_object, can_reuse)
                ^^^^^^^^^^^^^^^^^^^^^^^^^^^^^^^^
  File "C:\Users\nhanh\AppData\Local\Programs\Python\Python312\Lib\site-packages\django\db\models\sql\query.py", line 1678, in _add_q
    child_clause, needed_inner = self.build_filter(
                                 ^^^^^^^^^^^^^^^^^^
  File "C:\Users\nhanh\AppData\Local\Programs\Python\Python312\Lib\site-packages\django\db\models\sql\query.py", line 1588, in build_filter
    condition = self.build_lookup(lookups, col, value)
                ^^^^^^^^^^^^^^^^^^^^^^^^^^^^^^^^^^^^^^
  File "C:\Users\nhanh\AppData\Local\Programs\Python\Python312\Lib\site-packages\django\db\models\sql\query.py", line 1415, in build_lookup
    lookup = lookup_class(lhs, rhs)
             ^^^^^^^^^^^^^^^^^^^^^^
  File "C:\Users\nhanh\AppData\Local\Programs\Python\Python312\Lib\site-packages\django\db\models\lookups.py", line 38, in __init__
    self.rhs = self.get_prep_lookup()
               ^^^^^^^^^^^^^^^^^^^^^^
  File "C:\Users\nhanh\AppData\Local\Programs\Python\Python312\Lib\site-packages\django\db\models\fields\related_lookups.py", line 112, in get_prep_lookup
    self.rhs = target_field.get_prep_value(self.rhs)
               ^^^^^^^^^^^^^^^^^^^^^^^^^^^^^^^^^^^^^
  File "C:\Users\nhanh\AppData\Local\Programs\Python\Python312\Lib\site-packages\django\db\models\fields\__init__.py", line 2750, in get_prep_value
    return self.to_python(value)
           ^^^^^^^^^^^^^^^^^^^^^
  File "C:\Users\nhanh\AppData\Local\Programs\Python\Python312\Lib\site-packages\django\db\models\fields\__init__.py", line 2768, in to_python
    raise exceptions.ValidationError(
django.core.exceptions.ValidationError: ['“AnonymousUser” is not a valid UUID.']
WARNING 2025-08-01 08:45:47,358 base 25732 15668 view's GroupViewSet raised exception during schema generation; use `getattr(self, 'swagger_fake_view', False)` to detect and short-circuit this
Traceback (most recent call last):
  File "C:\Users\nhanh\AppData\Local\Programs\Python\Python312\Lib\site-packages\django\db\models\fields\__init__.py", line 2766, in to_python
    return uuid.UUID(**{input_form: value})
           ^^^^^^^^^^^^^^^^^^^^^^^^^^^^^^^^
  File "C:\Users\nhanh\AppData\Local\Programs\Python\Python312\Lib\uuid.py", line 175, in __init__
    hex = hex.replace('urn:', '').replace('uuid:', '')
          ^^^^^^^^^^^
AttributeError: 'AnonymousUser' object has no attribute 'replace'

During handling of the above exception, another exception occurred:

Traceback (most recent call last):
  File "C:\Users\nhanh\AppData\Local\Programs\Python\Python312\Lib\site-packages\drf_yasg\inspectors\base.py", line 42, in call_view_method
    return view_method()
           ^^^^^^^^^^^^^
  File "D:\Study\DoAnNganh\PlanPal\planpalapp\planpals\views.py", line 232, in get_queryset
    return Group.objects.filter(
           ^^^^^^^^^^^^^^^^^^^^^
  File "C:\Users\nhanh\AppData\Local\Programs\Python\Python312\Lib\site-packages\django\db\models\manager.py", line 87, in manager_method
    return getattr(self.get_queryset(), name)(*args, **kwargs)
           ^^^^^^^^^^^^^^^^^^^^^^^^^^^^^^^^^^^^^^^^^^^^^^^^^^^
  File "C:\Users\nhanh\AppData\Local\Programs\Python\Python312\Lib\site-packages\django\db\models\query.py", line 1493, in filter
    return self._filter_or_exclude(False, args, kwargs)
           ^^^^^^^^^^^^^^^^^^^^^^^^^^^^^^^^^^^^^^^^^^^^
  File "C:\Users\nhanh\AppData\Local\Programs\Python\Python312\Lib\site-packages\django\db\models\query.py", line 1511, in _filter_or_exclude
    clone._filter_or_exclude_inplace(negate, args, kwargs)
  File "C:\Users\nhanh\AppData\Local\Programs\Python\Python312\Lib\site-packages\django\db\models\query.py", line 1518, in _filter_or_exclude_inplace
    self._query.add_q(Q(*args, **kwargs))
  File "C:\Users\nhanh\AppData\Local\Programs\Python\Python312\Lib\site-packages\django\db\models\sql\query.py", line 1646, in add_q
    clause, _ = self._add_q(q_object, can_reuse)
                ^^^^^^^^^^^^^^^^^^^^^^^^^^^^^^^^
  File "C:\Users\nhanh\AppData\Local\Programs\Python\Python312\Lib\site-packages\django\db\models\sql\query.py", line 1678, in _add_q
    child_clause, needed_inner = self.build_filter(
                                 ^^^^^^^^^^^^^^^^^^
  File "C:\Users\nhanh\AppData\Local\Programs\Python\Python312\Lib\site-packages\django\db\models\sql\query.py", line 1588, in build_filter
    condition = self.build_lookup(lookups, col, value)
                ^^^^^^^^^^^^^^^^^^^^^^^^^^^^^^^^^^^^^^
  File "C:\Users\nhanh\AppData\Local\Programs\Python\Python312\Lib\site-packages\django\db\models\sql\query.py", line 1415, in build_lookup
    lookup = lookup_class(lhs, rhs)
             ^^^^^^^^^^^^^^^^^^^^^^
  File "C:\Users\nhanh\AppData\Local\Programs\Python\Python312\Lib\site-packages\django\db\models\lookups.py", line 38, in __init__
    self.rhs = self.get_prep_lookup()
               ^^^^^^^^^^^^^^^^^^^^^^
  File "C:\Users\nhanh\AppData\Local\Programs\Python\Python312\Lib\site-packages\django\db\models\fields\related_lookups.py", line 112, in get_prep_lookup
    self.rhs = target_field.get_prep_value(self.rhs)
               ^^^^^^^^^^^^^^^^^^^^^^^^^^^^^^^^^^^^^
  File "C:\Users\nhanh\AppData\Local\Programs\Python\Python312\Lib\site-packages\django\db\models\fields\__init__.py", line 2750, in get_prep_value
    return self.to_python(value)
           ^^^^^^^^^^^^^^^^^^^^^
  File "C:\Users\nhanh\AppData\Local\Programs\Python\Python312\Lib\site-packages\django\db\models\fields\__init__.py", line 2768, in to_python
    raise exceptions.ValidationError(
django.core.exceptions.ValidationError: ['“AnonymousUser” is not a valid UUID.']
WARNING 2025-08-01 08:45:47,361 base 25732 15668 view's PlanViewSet raised exception during schema generation; use `getattr(self, 'swagger_fake_view', False)` to detect and short-circuit this
Traceback (most recent call last):
  File "C:\Users\nhanh\AppData\Local\Programs\Python\Python312\Lib\site-packages\django\db\models\fields\__init__.py", line 2766, in to_python
    return uuid.UUID(**{input_form: value})
           ^^^^^^^^^^^^^^^^^^^^^^^^^^^^^^^^
  File "C:\Users\nhanh\AppData\Local\Programs\Python\Python312\Lib\uuid.py", line 175, in __init__
    hex = hex.replace('urn:', '').replace('uuid:', '')
          ^^^^^^^^^^^
AttributeError: 'AnonymousUser' object has no attribute 'replace'

During handling of the above exception, another exception occurred:

Traceback (most recent call last):
  File "C:\Users\nhanh\AppData\Local\Programs\Python\Python312\Lib\site-packages\drf_yasg\inspectors\base.py", line 42, in call_view_method
    return view_method()
           ^^^^^^^^^^^^^
  File "D:\Study\DoAnNganh\PlanPal\planpalapp\planpals\views.py", line 393, in get_queryset
    return Plan.objects.filter(
           ^^^^^^^^^^^^^^^^^^^^
  File "C:\Users\nhanh\AppData\Local\Programs\Python\Python312\Lib\site-packages\django\db\models\manager.py", line 87, in manager_method
    return getattr(self.get_queryset(), name)(*args, **kwargs)
           ^^^^^^^^^^^^^^^^^^^^^^^^^^^^^^^^^^^^^^^^^^^^^^^^^^^
  File "C:\Users\nhanh\AppData\Local\Programs\Python\Python312\Lib\site-packages\django\db\models\query.py", line 1493, in filter
    return self._filter_or_exclude(False, args, kwargs)
           ^^^^^^^^^^^^^^^^^^^^^^^^^^^^^^^^^^^^^^^^^^^^
  File "C:\Users\nhanh\AppData\Local\Programs\Python\Python312\Lib\site-packages\django\db\models\query.py", line 1511, in _filter_or_exclude
    clone._filter_or_exclude_inplace(negate, args, kwargs)
  File "C:\Users\nhanh\AppData\Local\Programs\Python\Python312\Lib\site-packages\django\db\models\query.py", line 1518, in _filter_or_exclude_inplace
    self._query.add_q(Q(*args, **kwargs))
  File "C:\Users\nhanh\AppData\Local\Programs\Python\Python312\Lib\site-packages\django\db\models\sql\query.py", line 1646, in add_q
    clause, _ = self._add_q(q_object, can_reuse)
                ^^^^^^^^^^^^^^^^^^^^^^^^^^^^^^^^
  File "C:\Users\nhanh\AppData\Local\Programs\Python\Python312\Lib\site-packages\django\db\models\sql\query.py", line 1678, in _add_q
    child_clause, needed_inner = self.build_filter(
                                 ^^^^^^^^^^^^^^^^^^
  File "C:\Users\nhanh\AppData\Local\Programs\Python\Python312\Lib\site-packages\django\db\models\sql\query.py", line 1503, in build_filter
    return self._add_q(
           ^^^^^^^^^^^^
  File "C:\Users\nhanh\AppData\Local\Programs\Python\Python312\Lib\site-packages\django\db\models\sql\query.py", line 1678, in _add_q
    child_clause, needed_inner = self.build_filter(
                                 ^^^^^^^^^^^^^^^^^^
  File "C:\Users\nhanh\AppData\Local\Programs\Python\Python312\Lib\site-packages\django\db\models\sql\query.py", line 1588, in build_filter
    condition = self.build_lookup(lookups, col, value)
                ^^^^^^^^^^^^^^^^^^^^^^^^^^^^^^^^^^^^^^
  File "C:\Users\nhanh\AppData\Local\Programs\Python\Python312\Lib\site-packages\django\db\models\sql\query.py", line 1415, in build_lookup
    lookup = lookup_class(lhs, rhs)
             ^^^^^^^^^^^^^^^^^^^^^^
  File "C:\Users\nhanh\AppData\Local\Programs\Python\Python312\Lib\site-packages\django\db\models\lookups.py", line 38, in __init__
    self.rhs = self.get_prep_lookup()
               ^^^^^^^^^^^^^^^^^^^^^^
  File "C:\Users\nhanh\AppData\Local\Programs\Python\Python312\Lib\site-packages\django\db\models\fields\related_lookups.py", line 112, in get_prep_lookup
    self.rhs = target_field.get_prep_value(self.rhs)
               ^^^^^^^^^^^^^^^^^^^^^^^^^^^^^^^^^^^^^
  File "C:\Users\nhanh\AppData\Local\Programs\Python\Python312\Lib\site-packages\django\db\models\fields\__init__.py", line 2750, in get_prep_value
    return self.to_python(value)
           ^^^^^^^^^^^^^^^^^^^^^
  File "C:\Users\nhanh\AppData\Local\Programs\Python\Python312\Lib\site-packages\django\db\models\fields\__init__.py", line 2768, in to_python
    raise exceptions.ValidationError(
django.core.exceptions.ValidationError: ['“AnonymousUser” is not a valid UUID.']
WARNING 2025-08-01 08:45:47,366 base 25732 15668 view's PlanViewSet raised exception during schema generation; use `getattr(self, 'swagger_fake_view', False)` to detect and short-circuit this
Traceback (most recent call last):
  File "C:\Users\nhanh\AppData\Local\Programs\Python\Python312\Lib\site-packages\django\db\models\fields\__init__.py", line 2766, in to_python
    return uuid.UUID(**{input_form: value})
           ^^^^^^^^^^^^^^^^^^^^^^^^^^^^^^^^
  File "C:\Users\nhanh\AppData\Local\Programs\Python\Python312\Lib\uuid.py", line 175, in __init__
    hex = hex.replace('urn:', '').replace('uuid:', '')
          ^^^^^^^^^^^
AttributeError: 'AnonymousUser' object has no attribute 'replace'

During handling of the above exception, another exception occurred:

Traceback (most recent call last):
  File "C:\Users\nhanh\AppData\Local\Programs\Python\Python312\Lib\site-packages\drf_yasg\inspectors\base.py", line 42, in call_view_method
    return view_method()
           ^^^^^^^^^^^^^
  File "D:\Study\DoAnNganh\PlanPal\planpalapp\planpals\views.py", line 393, in get_queryset
    return Plan.objects.filter(
           ^^^^^^^^^^^^^^^^^^^^
  File "C:\Users\nhanh\AppData\Local\Programs\Python\Python312\Lib\site-packages\django\db\models\manager.py", line 87, in manager_method
    return getattr(self.get_queryset(), name)(*args, **kwargs)
           ^^^^^^^^^^^^^^^^^^^^^^^^^^^^^^^^^^^^^^^^^^^^^^^^^^^
  File "C:\Users\nhanh\AppData\Local\Programs\Python\Python312\Lib\site-packages\django\db\models\query.py", line 1493, in filter
    return self._filter_or_exclude(False, args, kwargs)
           ^^^^^^^^^^^^^^^^^^^^^^^^^^^^^^^^^^^^^^^^^^^^
  File "C:\Users\nhanh\AppData\Local\Programs\Python\Python312\Lib\site-packages\django\db\models\query.py", line 1511, in _filter_or_exclude
    clone._filter_or_exclude_inplace(negate, args, kwargs)
  File "C:\Users\nhanh\AppData\Local\Programs\Python\Python312\Lib\site-packages\django\db\models\query.py", line 1518, in _filter_or_exclude_inplace
    self._query.add_q(Q(*args, **kwargs))
  File "C:\Users\nhanh\AppData\Local\Programs\Python\Python312\Lib\site-packages\django\db\models\sql\query.py", line 1646, in add_q
    clause, _ = self._add_q(q_object, can_reuse)
                ^^^^^^^^^^^^^^^^^^^^^^^^^^^^^^^^
  File "C:\Users\nhanh\AppData\Local\Programs\Python\Python312\Lib\site-packages\django\db\models\sql\query.py", line 1678, in _add_q
    child_clause, needed_inner = self.build_filter(
                                 ^^^^^^^^^^^^^^^^^^
  File "C:\Users\nhanh\AppData\Local\Programs\Python\Python312\Lib\site-packages\django\db\models\sql\query.py", line 1503, in build_filter
    return self._add_q(
           ^^^^^^^^^^^^
  File "C:\Users\nhanh\AppData\Local\Programs\Python\Python312\Lib\site-packages\django\db\models\sql\query.py", line 1678, in _add_q
    child_clause, needed_inner = self.build_filter(
                                 ^^^^^^^^^^^^^^^^^^
  File "C:\Users\nhanh\AppData\Local\Programs\Python\Python312\Lib\site-packages\django\db\models\sql\query.py", line 1588, in build_filter
    condition = self.build_lookup(lookups, col, value)
                ^^^^^^^^^^^^^^^^^^^^^^^^^^^^^^^^^^^^^^
  File "C:\Users\nhanh\AppData\Local\Programs\Python\Python312\Lib\site-packages\django\db\models\sql\query.py", line 1415, in build_lookup
    lookup = lookup_class(lhs, rhs)
             ^^^^^^^^^^^^^^^^^^^^^^
  File "C:\Users\nhanh\AppData\Local\Programs\Python\Python312\Lib\site-packages\django\db\models\lookups.py", line 38, in __init__
    self.rhs = self.get_prep_lookup()
               ^^^^^^^^^^^^^^^^^^^^^^
  File "C:\Users\nhanh\AppData\Local\Programs\Python\Python312\Lib\site-packages\django\db\models\fields\related_lookups.py", line 112, in get_prep_lookup
    self.rhs = target_field.get_prep_value(self.rhs)
               ^^^^^^^^^^^^^^^^^^^^^^^^^^^^^^^^^^^^^
  File "C:\Users\nhanh\AppData\Local\Programs\Python\Python312\Lib\site-packages\django\db\models\fields\__init__.py", line 2750, in get_prep_value
    return self.to_python(value)
           ^^^^^^^^^^^^^^^^^^^^^
  File "C:\Users\nhanh\AppData\Local\Programs\Python\Python312\Lib\site-packages\django\db\models\fields\__init__.py", line 2768, in to_python
    raise exceptions.ValidationError(
django.core.exceptions.ValidationError: ['“AnonymousUser” is not a valid UUID.']
WARNING 2025-08-01 08:45:47,371 base 25732 15668 view's PlanViewSet raised exception during schema generation; use `getattr(self, 'swagger_fake_view', False)` to detect and short-circuit this
Traceback (most recent call last):
  File "C:\Users\nhanh\AppData\Local\Programs\Python\Python312\Lib\site-packages\django\db\models\fields\__init__.py", line 2766, in to_python
    return uuid.UUID(**{input_form: value})
           ^^^^^^^^^^^^^^^^^^^^^^^^^^^^^^^^
  File "C:\Users\nhanh\AppData\Local\Programs\Python\Python312\Lib\uuid.py", line 175, in __init__
    hex = hex.replace('urn:', '').replace('uuid:', '')
          ^^^^^^^^^^^
AttributeError: 'AnonymousUser' object has no attribute 'replace'

During handling of the above exception, another exception occurred:

Traceback (most recent call last):
  File "C:\Users\nhanh\AppData\Local\Programs\Python\Python312\Lib\site-packages\drf_yasg\inspectors\base.py", line 42, in call_view_method
    return view_method()
           ^^^^^^^^^^^^^
  File "D:\Study\DoAnNganh\PlanPal\planpalapp\planpals\views.py", line 393, in get_queryset
    return Plan.objects.filter(
           ^^^^^^^^^^^^^^^^^^^^
  File "C:\Users\nhanh\AppData\Local\Programs\Python\Python312\Lib\site-packages\django\db\models\manager.py", line 87, in manager_method
    return getattr(self.get_queryset(), name)(*args, **kwargs)
           ^^^^^^^^^^^^^^^^^^^^^^^^^^^^^^^^^^^^^^^^^^^^^^^^^^^
  File "C:\Users\nhanh\AppData\Local\Programs\Python\Python312\Lib\site-packages\django\db\models\query.py", line 1493, in filter
    return self._filter_or_exclude(False, args, kwargs)
           ^^^^^^^^^^^^^^^^^^^^^^^^^^^^^^^^^^^^^^^^^^^^
  File "C:\Users\nhanh\AppData\Local\Programs\Python\Python312\Lib\site-packages\django\db\models\query.py", line 1511, in _filter_or_exclude
    clone._filter_or_exclude_inplace(negate, args, kwargs)
  File "C:\Users\nhanh\AppData\Local\Programs\Python\Python312\Lib\site-packages\django\db\models\query.py", line 1518, in _filter_or_exclude_inplace
    self._query.add_q(Q(*args, **kwargs))
  File "C:\Users\nhanh\AppData\Local\Programs\Python\Python312\Lib\site-packages\django\db\models\sql\query.py", line 1646, in add_q
    clause, _ = self._add_q(q_object, can_reuse)
                ^^^^^^^^^^^^^^^^^^^^^^^^^^^^^^^^
  File "C:\Users\nhanh\AppData\Local\Programs\Python\Python312\Lib\site-packages\django\db\models\sql\query.py", line 1678, in _add_q
    child_clause, needed_inner = self.build_filter(
                                 ^^^^^^^^^^^^^^^^^^
  File "C:\Users\nhanh\AppData\Local\Programs\Python\Python312\Lib\site-packages\django\db\models\sql\query.py", line 1503, in build_filter
    return self._add_q(
           ^^^^^^^^^^^^
  File "C:\Users\nhanh\AppData\Local\Programs\Python\Python312\Lib\site-packages\django\db\models\sql\query.py", line 1678, in _add_q
    child_clause, needed_inner = self.build_filter(
                                 ^^^^^^^^^^^^^^^^^^
  File "C:\Users\nhanh\AppData\Local\Programs\Python\Python312\Lib\site-packages\django\db\models\sql\query.py", line 1588, in build_filter
    condition = self.build_lookup(lookups, col, value)
                ^^^^^^^^^^^^^^^^^^^^^^^^^^^^^^^^^^^^^^
  File "C:\Users\nhanh\AppData\Local\Programs\Python\Python312\Lib\site-packages\django\db\models\sql\query.py", line 1415, in build_lookup
    lookup = lookup_class(lhs, rhs)
             ^^^^^^^^^^^^^^^^^^^^^^
  File "C:\Users\nhanh\AppData\Local\Programs\Python\Python312\Lib\site-packages\django\db\models\lookups.py", line 38, in __init__
    self.rhs = self.get_prep_lookup()
               ^^^^^^^^^^^^^^^^^^^^^^
  File "C:\Users\nhanh\AppData\Local\Programs\Python\Python312\Lib\site-packages\django\db\models\fields\related_lookups.py", line 112, in get_prep_lookup
    self.rhs = target_field.get_prep_value(self.rhs)
               ^^^^^^^^^^^^^^^^^^^^^^^^^^^^^^^^^^^^^
  File "C:\Users\nhanh\AppData\Local\Programs\Python\Python312\Lib\site-packages\django\db\models\fields\__init__.py", line 2750, in get_prep_value
    return self.to_python(value)
           ^^^^^^^^^^^^^^^^^^^^^
  File "C:\Users\nhanh\AppData\Local\Programs\Python\Python312\Lib\site-packages\django\db\models\fields\__init__.py", line 2768, in to_python
    raise exceptions.ValidationError(
django.core.exceptions.ValidationError: ['“AnonymousUser” is not a valid UUID.']
WARNING 2025-08-01 08:45:47,374 base 25732 15668 view's PlanViewSet raised exception during schema generation; use `getattr(self, 'swagger_fake_view', False)` to detect and short-circuit this
Traceback (most recent call last):
  File "C:\Users\nhanh\AppData\Local\Programs\Python\Python312\Lib\site-packages\django\db\models\fields\__init__.py", line 2766, in to_python
    return uuid.UUID(**{input_form: value})
           ^^^^^^^^^^^^^^^^^^^^^^^^^^^^^^^^
  File "C:\Users\nhanh\AppData\Local\Programs\Python\Python312\Lib\uuid.py", line 175, in __init__
    hex = hex.replace('urn:', '').replace('uuid:', '')
          ^^^^^^^^^^^
AttributeError: 'AnonymousUser' object has no attribute 'replace'

During handling of the above exception, another exception occurred:

Traceback (most recent call last):
  File "C:\Users\nhanh\AppData\Local\Programs\Python\Python312\Lib\site-packages\drf_yasg\inspectors\base.py", line 42, in call_view_method
    return view_method()
           ^^^^^^^^^^^^^
  File "D:\Study\DoAnNganh\PlanPal\planpalapp\planpals\views.py", line 393, in get_queryset
    return Plan.objects.filter(
           ^^^^^^^^^^^^^^^^^^^^
  File "C:\Users\nhanh\AppData\Local\Programs\Python\Python312\Lib\site-packages\django\db\models\manager.py", line 87, in manager_method
    return getattr(self.get_queryset(), name)(*args, **kwargs)
           ^^^^^^^^^^^^^^^^^^^^^^^^^^^^^^^^^^^^^^^^^^^^^^^^^^^
  File "C:\Users\nhanh\AppData\Local\Programs\Python\Python312\Lib\site-packages\django\db\models\query.py", line 1493, in filter
    return self._filter_or_exclude(False, args, kwargs)
           ^^^^^^^^^^^^^^^^^^^^^^^^^^^^^^^^^^^^^^^^^^^^
  File "C:\Users\nhanh\AppData\Local\Programs\Python\Python312\Lib\site-packages\django\db\models\query.py", line 1511, in _filter_or_exclude
    clone._filter_or_exclude_inplace(negate, args, kwargs)
  File "C:\Users\nhanh\AppData\Local\Programs\Python\Python312\Lib\site-packages\django\db\models\query.py", line 1518, in _filter_or_exclude_inplace
    self._query.add_q(Q(*args, **kwargs))
  File "C:\Users\nhanh\AppData\Local\Programs\Python\Python312\Lib\site-packages\django\db\models\sql\query.py", line 1646, in add_q
    clause, _ = self._add_q(q_object, can_reuse)
                ^^^^^^^^^^^^^^^^^^^^^^^^^^^^^^^^
  File "C:\Users\nhanh\AppData\Local\Programs\Python\Python312\Lib\site-packages\django\db\models\sql\query.py", line 1678, in _add_q
    child_clause, needed_inner = self.build_filter(
                                 ^^^^^^^^^^^^^^^^^^
  File "C:\Users\nhanh\AppData\Local\Programs\Python\Python312\Lib\site-packages\django\db\models\sql\query.py", line 1503, in build_filter
    return self._add_q(
           ^^^^^^^^^^^^
  File "C:\Users\nhanh\AppData\Local\Programs\Python\Python312\Lib\site-packages\django\db\models\sql\query.py", line 1678, in _add_q
    child_clause, needed_inner = self.build_filter(
                                 ^^^^^^^^^^^^^^^^^^
  File "C:\Users\nhanh\AppData\Local\Programs\Python\Python312\Lib\site-packages\django\db\models\sql\query.py", line 1588, in build_filter
    condition = self.build_lookup(lookups, col, value)
                ^^^^^^^^^^^^^^^^^^^^^^^^^^^^^^^^^^^^^^
  File "C:\Users\nhanh\AppData\Local\Programs\Python\Python312\Lib\site-packages\django\db\models\sql\query.py", line 1415, in build_lookup
    lookup = lookup_class(lhs, rhs)
             ^^^^^^^^^^^^^^^^^^^^^^
  File "C:\Users\nhanh\AppData\Local\Programs\Python\Python312\Lib\site-packages\django\db\models\lookups.py", line 38, in __init__
    self.rhs = self.get_prep_lookup()
               ^^^^^^^^^^^^^^^^^^^^^^
  File "C:\Users\nhanh\AppData\Local\Programs\Python\Python312\Lib\site-packages\django\db\models\fields\related_lookups.py", line 112, in get_prep_lookup
    self.rhs = target_field.get_prep_value(self.rhs)
               ^^^^^^^^^^^^^^^^^^^^^^^^^^^^^^^^^^^^^
  File "C:\Users\nhanh\AppData\Local\Programs\Python\Python312\Lib\site-packages\django\db\models\fields\__init__.py", line 2750, in get_prep_value
    return self.to_python(value)
           ^^^^^^^^^^^^^^^^^^^^^
  File "C:\Users\nhanh\AppData\Local\Programs\Python\Python312\Lib\site-packages\django\db\models\fields\__init__.py", line 2768, in to_python
    raise exceptions.ValidationError(
django.core.exceptions.ValidationError: ['“AnonymousUser” is not a valid UUID.']
WARNING 2025-08-01 08:45:47,378 base 25732 15668 view's ChatMessageViewSet raised exception during schema generation; use `getattr(self, 'swagger_fake_view', False)` to detect and short-circuit this
Traceback (most recent call last):
  File "C:\Users\nhanh\AppData\Local\Programs\Python\Python312\Lib\site-packages\django\db\models\fields\__init__.py", line 2766, in to_python
    return uuid.UUID(**{input_form: value})
           ^^^^^^^^^^^^^^^^^^^^^^^^^^^^^^^^
  File "C:\Users\nhanh\AppData\Local\Programs\Python\Python312\Lib\uuid.py", line 175, in __init__
    hex = hex.replace('urn:', '').replace('uuid:', '')
          ^^^^^^^^^^^
AttributeError: 'AnonymousUser' object has no attribute 'replace'

During handling of the above exception, another exception occurred:

Traceback (most recent call last):
  File "C:\Users\nhanh\AppData\Local\Programs\Python\Python312\Lib\site-packages\drf_yasg\inspectors\base.py", line 42, in call_view_method
    return view_method()
           ^^^^^^^^^^^^^
  File "D:\Study\DoAnNganh\PlanPal\planpalapp\planpals\views.py", line 610, in get_queryset
    return ChatMessage.objects.filter(
           ^^^^^^^^^^^^^^^^^^^^^^^^^^^
  File "C:\Users\nhanh\AppData\Local\Programs\Python\Python312\Lib\site-packages\django\db\models\manager.py", line 87, in manager_method
    return getattr(self.get_queryset(), name)(*args, **kwargs)
           ^^^^^^^^^^^^^^^^^^^^^^^^^^^^^^^^^^^^^^^^^^^^^^^^^^^
  File "C:\Users\nhanh\AppData\Local\Programs\Python\Python312\Lib\site-packages\django\db\models\query.py", line 1493, in filter
    return self._filter_or_exclude(False, args, kwargs)
           ^^^^^^^^^^^^^^^^^^^^^^^^^^^^^^^^^^^^^^^^^^^^
  File "C:\Users\nhanh\AppData\Local\Programs\Python\Python312\Lib\site-packages\django\db\models\query.py", line 1511, in _filter_or_exclude
    clone._filter_or_exclude_inplace(negate, args, kwargs)
  File "C:\Users\nhanh\AppData\Local\Programs\Python\Python312\Lib\site-packages\django\db\models\query.py", line 1518, in _filter_or_exclude_inplace
    self._query.add_q(Q(*args, **kwargs))
  File "C:\Users\nhanh\AppData\Local\Programs\Python\Python312\Lib\site-packages\django\db\models\sql\query.py", line 1646, in add_q
    clause, _ = self._add_q(q_object, can_reuse)
                ^^^^^^^^^^^^^^^^^^^^^^^^^^^^^^^^
  File "C:\Users\nhanh\AppData\Local\Programs\Python\Python312\Lib\site-packages\django\db\models\sql\query.py", line 1678, in _add_q
    child_clause, needed_inner = self.build_filter(
                                 ^^^^^^^^^^^^^^^^^^
  File "C:\Users\nhanh\AppData\Local\Programs\Python\Python312\Lib\site-packages\django\db\models\sql\query.py", line 1588, in build_filter
    condition = self.build_lookup(lookups, col, value)
                ^^^^^^^^^^^^^^^^^^^^^^^^^^^^^^^^^^^^^^
  File "C:\Users\nhanh\AppData\Local\Programs\Python\Python312\Lib\site-packages\django\db\models\sql\query.py", line 1415, in build_lookup
    lookup = lookup_class(lhs, rhs)
             ^^^^^^^^^^^^^^^^^^^^^^
  File "C:\Users\nhanh\AppData\Local\Programs\Python\Python312\Lib\site-packages\django\db\models\lookups.py", line 38, in __init__
    self.rhs = self.get_prep_lookup()
               ^^^^^^^^^^^^^^^^^^^^^^
  File "C:\Users\nhanh\AppData\Local\Programs\Python\Python312\Lib\site-packages\django\db\models\fields\related_lookups.py", line 112, in get_prep_lookup
    self.rhs = target_field.get_prep_value(self.rhs)
               ^^^^^^^^^^^^^^^^^^^^^^^^^^^^^^^^^^^^^
  File "C:\Users\nhanh\AppData\Local\Programs\Python\Python312\Lib\site-packages\django\db\models\fields\__init__.py", line 2750, in get_prep_value
    return self.to_python(value)
           ^^^^^^^^^^^^^^^^^^^^^
  File "C:\Users\nhanh\AppData\Local\Programs\Python\Python312\Lib\site-packages\django\db\models\fields\__init__.py", line 2768, in to_python
    raise exceptions.ValidationError(
django.core.exceptions.ValidationError: ['“AnonymousUser” is not a valid UUID.']
WARNING 2025-08-01 08:45:47,381 base 25732 15668 view's PlanActivityViewSet raised exception during schema generation; use `getattr(self, 'swagger_fake_view', False)` to detect and short-circuit this
Traceback (most recent call last):
  File "C:\Users\nhanh\AppData\Local\Programs\Python\Python312\Lib\site-packages\django\db\models\fields\__init__.py", line 2766, in to_python
    return uuid.UUID(**{input_form: value})
           ^^^^^^^^^^^^^^^^^^^^^^^^^^^^^^^^
  File "C:\Users\nhanh\AppData\Local\Programs\Python\Python312\Lib\uuid.py", line 175, in __init__
    hex = hex.replace('urn:', '').replace('uuid:', '')
          ^^^^^^^^^^^
AttributeError: 'AnonymousUser' object has no attribute 'replace'

During handling of the above exception, another exception occurred:

Traceback (most recent call last):
  File "C:\Users\nhanh\AppData\Local\Programs\Python\Python312\Lib\site-packages\drf_yasg\inspectors\base.py", line 42, in call_view_method
    return view_method()
           ^^^^^^^^^^^^^
  File "D:\Study\DoAnNganh\PlanPal\planpalapp\planpals\views.py", line 805, in get_queryset
    return PlanActivity.objects.filter(
           ^^^^^^^^^^^^^^^^^^^^^^^^^^^^
  File "C:\Users\nhanh\AppData\Local\Programs\Python\Python312\Lib\site-packages\django\db\models\manager.py", line 87, in manager_method
    return getattr(self.get_queryset(), name)(*args, **kwargs)
           ^^^^^^^^^^^^^^^^^^^^^^^^^^^^^^^^^^^^^^^^^^^^^^^^^^^
  File "C:\Users\nhanh\AppData\Local\Programs\Python\Python312\Lib\site-packages\django\db\models\query.py", line 1493, in filter
    return self._filter_or_exclude(False, args, kwargs)
           ^^^^^^^^^^^^^^^^^^^^^^^^^^^^^^^^^^^^^^^^^^^^
  File "C:\Users\nhanh\AppData\Local\Programs\Python\Python312\Lib\site-packages\django\db\models\query.py", line 1511, in _filter_or_exclude
    clone._filter_or_exclude_inplace(negate, args, kwargs)
  File "C:\Users\nhanh\AppData\Local\Programs\Python\Python312\Lib\site-packages\django\db\models\query.py", line 1518, in _filter_or_exclude_inplace
    self._query.add_q(Q(*args, **kwargs))
  File "C:\Users\nhanh\AppData\Local\Programs\Python\Python312\Lib\site-packages\django\db\models\sql\query.py", line 1646, in add_q
    clause, _ = self._add_q(q_object, can_reuse)
                ^^^^^^^^^^^^^^^^^^^^^^^^^^^^^^^^
  File "C:\Users\nhanh\AppData\Local\Programs\Python\Python312\Lib\site-packages\django\db\models\sql\query.py", line 1678, in _add_q
    child_clause, needed_inner = self.build_filter(
                                 ^^^^^^^^^^^^^^^^^^
  File "C:\Users\nhanh\AppData\Local\Programs\Python\Python312\Lib\site-packages\django\db\models\sql\query.py", line 1588, in build_filter
    condition = self.build_lookup(lookups, col, value)
                ^^^^^^^^^^^^^^^^^^^^^^^^^^^^^^^^^^^^^^
  File "C:\Users\nhanh\AppData\Local\Programs\Python\Python312\Lib\site-packages\django\db\models\sql\query.py", line 1415, in build_lookup
    lookup = lookup_class(lhs, rhs)
             ^^^^^^^^^^^^^^^^^^^^^^
  File "C:\Users\nhanh\AppData\Local\Programs\Python\Python312\Lib\site-packages\django\db\models\lookups.py", line 38, in __init__
    self.rhs = self.get_prep_lookup()
               ^^^^^^^^^^^^^^^^^^^^^^
  File "C:\Users\nhanh\AppData\Local\Programs\Python\Python312\Lib\site-packages\django\db\models\fields\related_lookups.py", line 112, in get_prep_lookup
    self.rhs = target_field.get_prep_value(self.rhs)
               ^^^^^^^^^^^^^^^^^^^^^^^^^^^^^^^^^^^^^
  File "C:\Users\nhanh\AppData\Local\Programs\Python\Python312\Lib\site-packages\django\db\models\fields\__init__.py", line 2750, in get_prep_value
    return self.to_python(value)
           ^^^^^^^^^^^^^^^^^^^^^
  File "C:\Users\nhanh\AppData\Local\Programs\Python\Python312\Lib\site-packages\django\db\models\fields\__init__.py", line 2768, in to_python
    raise exceptions.ValidationError(
django.core.exceptions.ValidationError: ['“AnonymousUser” is not a valid UUID.']
WARNING 2025-08-01 08:45:47,390 base 25732 15668 view's GroupViewSet raised exception during schema generation; use `getattr(self, 'swagger_fake_view', False)` to detect and short-circuit this
Traceback (most recent call last):
  File "C:\Users\nhanh\AppData\Local\Programs\Python\Python312\Lib\site-packages\django\db\models\fields\__init__.py", line 2766, in to_python
    return uuid.UUID(**{input_form: value})
           ^^^^^^^^^^^^^^^^^^^^^^^^^^^^^^^^
  File "C:\Users\nhanh\AppData\Local\Programs\Python\Python312\Lib\uuid.py", line 175, in __init__
    hex = hex.replace('urn:', '').replace('uuid:', '')
          ^^^^^^^^^^^
AttributeError: 'AnonymousUser' object has no attribute 'replace'

During handling of the above exception, another exception occurred:

Traceback (most recent call last):
  File "C:\Users\nhanh\AppData\Local\Programs\Python\Python312\Lib\site-packages\drf_yasg\inspectors\base.py", line 42, in call_view_method
    return view_method()
           ^^^^^^^^^^^^^
  File "D:\Study\DoAnNganh\PlanPal\planpalapp\planpals\views.py", line 232, in get_queryset
    return Group.objects.filter(
           ^^^^^^^^^^^^^^^^^^^^^
  File "C:\Users\nhanh\AppData\Local\Programs\Python\Python312\Lib\site-packages\django\db\models\manager.py", line 87, in manager_method
    return getattr(self.get_queryset(), name)(*args, **kwargs)
           ^^^^^^^^^^^^^^^^^^^^^^^^^^^^^^^^^^^^^^^^^^^^^^^^^^^
  File "C:\Users\nhanh\AppData\Local\Programs\Python\Python312\Lib\site-packages\django\db\models\query.py", line 1493, in filter
    return self._filter_or_exclude(False, args, kwargs)
           ^^^^^^^^^^^^^^^^^^^^^^^^^^^^^^^^^^^^^^^^^^^^
  File "C:\Users\nhanh\AppData\Local\Programs\Python\Python312\Lib\site-packages\django\db\models\query.py", line 1511, in _filter_or_exclude
    clone._filter_or_exclude_inplace(negate, args, kwargs)
  File "C:\Users\nhanh\AppData\Local\Programs\Python\Python312\Lib\site-packages\django\db\models\query.py", line 1518, in _filter_or_exclude_inplace
    self._query.add_q(Q(*args, **kwargs))
  File "C:\Users\nhanh\AppData\Local\Programs\Python\Python312\Lib\site-packages\django\db\models\sql\query.py", line 1646, in add_q
    clause, _ = self._add_q(q_object, can_reuse)
                ^^^^^^^^^^^^^^^^^^^^^^^^^^^^^^^^
  File "C:\Users\nhanh\AppData\Local\Programs\Python\Python312\Lib\site-packages\django\db\models\sql\query.py", line 1678, in _add_q
    child_clause, needed_inner = self.build_filter(
                                 ^^^^^^^^^^^^^^^^^^
  File "C:\Users\nhanh\AppData\Local\Programs\Python\Python312\Lib\site-packages\django\db\models\sql\query.py", line 1588, in build_filter
    condition = self.build_lookup(lookups, col, value)
                ^^^^^^^^^^^^^^^^^^^^^^^^^^^^^^^^^^^^^^
  File "C:\Users\nhanh\AppData\Local\Programs\Python\Python312\Lib\site-packages\django\db\models\sql\query.py", line 1415, in build_lookup
    lookup = lookup_class(lhs, rhs)
             ^^^^^^^^^^^^^^^^^^^^^^
  File "C:\Users\nhanh\AppData\Local\Programs\Python\Python312\Lib\site-packages\django\db\models\lookups.py", line 38, in __init__
    self.rhs = self.get_prep_lookup()
               ^^^^^^^^^^^^^^^^^^^^^^
  File "C:\Users\nhanh\AppData\Local\Programs\Python\Python312\Lib\site-packages\django\db\models\fields\related_lookups.py", line 112, in get_prep_lookup
    self.rhs = target_field.get_prep_value(self.rhs)
               ^^^^^^^^^^^^^^^^^^^^^^^^^^^^^^^^^^^^^
  File "C:\Users\nhanh\AppData\Local\Programs\Python\Python312\Lib\site-packages\django\db\models\fields\__init__.py", line 2750, in get_prep_value
    return self.to_python(value)
           ^^^^^^^^^^^^^^^^^^^^^
  File "C:\Users\nhanh\AppData\Local\Programs\Python\Python312\Lib\site-packages\django\db\models\fields\__init__.py", line 2768, in to_python
    raise exceptions.ValidationError(
django.core.exceptions.ValidationError: ['“AnonymousUser” is not a valid UUID.']
WARNING 2025-08-01 08:45:47,394 base 25732 15668 view's PlanViewSet raised exception during schema generation; use `getattr(self, 'swagger_fake_view', False)` to detect and short-circuit this
Traceback (most recent call last):
  File "C:\Users\nhanh\AppData\Local\Programs\Python\Python312\Lib\site-packages\django\db\models\fields\__init__.py", line 2766, in to_python
    return uuid.UUID(**{input_form: value})
           ^^^^^^^^^^^^^^^^^^^^^^^^^^^^^^^^
  File "C:\Users\nhanh\AppData\Local\Programs\Python\Python312\Lib\uuid.py", line 175, in __init__
    hex = hex.replace('urn:', '').replace('uuid:', '')
          ^^^^^^^^^^^
AttributeError: 'AnonymousUser' object has no attribute 'replace'

During handling of the above exception, another exception occurred:

Traceback (most recent call last):
  File "C:\Users\nhanh\AppData\Local\Programs\Python\Python312\Lib\site-packages\drf_yasg\inspectors\base.py", line 42, in call_view_method
    return view_method()
           ^^^^^^^^^^^^^
  File "D:\Study\DoAnNganh\PlanPal\planpalapp\planpals\views.py", line 393, in get_queryset
    return Plan.objects.filter(
           ^^^^^^^^^^^^^^^^^^^^
  File "C:\Users\nhanh\AppData\Local\Programs\Python\Python312\Lib\site-packages\django\db\models\manager.py", line 87, in manager_method
    return getattr(self.get_queryset(), name)(*args, **kwargs)
           ^^^^^^^^^^^^^^^^^^^^^^^^^^^^^^^^^^^^^^^^^^^^^^^^^^^
  File "C:\Users\nhanh\AppData\Local\Programs\Python\Python312\Lib\site-packages\django\db\models\query.py", line 1493, in filter
    return self._filter_or_exclude(False, args, kwargs)
           ^^^^^^^^^^^^^^^^^^^^^^^^^^^^^^^^^^^^^^^^^^^^
  File "C:\Users\nhanh\AppData\Local\Programs\Python\Python312\Lib\site-packages\django\db\models\query.py", line 1511, in _filter_or_exclude
    clone._filter_or_exclude_inplace(negate, args, kwargs)
  File "C:\Users\nhanh\AppData\Local\Programs\Python\Python312\Lib\site-packages\django\db\models\query.py", line 1518, in _filter_or_exclude_inplace
    self._query.add_q(Q(*args, **kwargs))
  File "C:\Users\nhanh\AppData\Local\Programs\Python\Python312\Lib\site-packages\django\db\models\sql\query.py", line 1646, in add_q
    clause, _ = self._add_q(q_object, can_reuse)
                ^^^^^^^^^^^^^^^^^^^^^^^^^^^^^^^^
  File "C:\Users\nhanh\AppData\Local\Programs\Python\Python312\Lib\site-packages\django\db\models\sql\query.py", line 1678, in _add_q
    child_clause, needed_inner = self.build_filter(
                                 ^^^^^^^^^^^^^^^^^^
  File "C:\Users\nhanh\AppData\Local\Programs\Python\Python312\Lib\site-packages\django\db\models\sql\query.py", line 1503, in build_filter
    return self._add_q(
           ^^^^^^^^^^^^
  File "C:\Users\nhanh\AppData\Local\Programs\Python\Python312\Lib\site-packages\django\db\models\sql\query.py", line 1678, in _add_q
    child_clause, needed_inner = self.build_filter(
                                 ^^^^^^^^^^^^^^^^^^
  File "C:\Users\nhanh\AppData\Local\Programs\Python\Python312\Lib\site-packages\django\db\models\sql\query.py", line 1588, in build_filter
    condition = self.build_lookup(lookups, col, value)
                ^^^^^^^^^^^^^^^^^^^^^^^^^^^^^^^^^^^^^^
  File "C:\Users\nhanh\AppData\Local\Programs\Python\Python312\Lib\site-packages\django\db\models\sql\query.py", line 1415, in build_lookup
    lookup = lookup_class(lhs, rhs)
             ^^^^^^^^^^^^^^^^^^^^^^
  File "C:\Users\nhanh\AppData\Local\Programs\Python\Python312\Lib\site-packages\django\db\models\lookups.py", line 38, in __init__
    self.rhs = self.get_prep_lookup()
               ^^^^^^^^^^^^^^^^^^^^^^
  File "C:\Users\nhanh\AppData\Local\Programs\Python\Python312\Lib\site-packages\django\db\models\fields\related_lookups.py", line 112, in get_prep_lookup
    self.rhs = target_field.get_prep_value(self.rhs)
               ^^^^^^^^^^^^^^^^^^^^^^^^^^^^^^^^^^^^^
  File "C:\Users\nhanh\AppData\Local\Programs\Python\Python312\Lib\site-packages\django\db\models\fields\__init__.py", line 2750, in get_prep_value
    return self.to_python(value)
           ^^^^^^^^^^^^^^^^^^^^^
  File "C:\Users\nhanh\AppData\Local\Programs\Python\Python312\Lib\site-packages\django\db\models\fields\__init__.py", line 2768, in to_python
    raise exceptions.ValidationError(
django.core.exceptions.ValidationError: ['“AnonymousUser” is not a valid UUID.']
WARNING 2025-08-01 08:45:47,399 base 25732 15668 view's GroupViewSet raised exception during schema generation; use `getattr(self, 'swagger_fake_view', False)` to detect and short-circuit this
Traceback (most recent call last):
  File "C:\Users\nhanh\AppData\Local\Programs\Python\Python312\Lib\site-packages\django\db\models\fields\__init__.py", line 2766, in to_python
    return uuid.UUID(**{input_form: value})
           ^^^^^^^^^^^^^^^^^^^^^^^^^^^^^^^^
  File "C:\Users\nhanh\AppData\Local\Programs\Python\Python312\Lib\uuid.py", line 175, in __init__
    hex = hex.replace('urn:', '').replace('uuid:', '')
          ^^^^^^^^^^^
AttributeError: 'AnonymousUser' object has no attribute 'replace'

During handling of the above exception, another exception occurred:

Traceback (most recent call last):
  File "C:\Users\nhanh\AppData\Local\Programs\Python\Python312\Lib\site-packages\drf_yasg\inspectors\base.py", line 42, in call_view_method
    return view_method()
           ^^^^^^^^^^^^^
  File "D:\Study\DoAnNganh\PlanPal\planpalapp\planpals\views.py", line 232, in get_queryset
    return Group.objects.filter(
           ^^^^^^^^^^^^^^^^^^^^^
  File "C:\Users\nhanh\AppData\Local\Programs\Python\Python312\Lib\site-packages\django\db\models\manager.py", line 87, in manager_method
    return getattr(self.get_queryset(), name)(*args, **kwargs)
           ^^^^^^^^^^^^^^^^^^^^^^^^^^^^^^^^^^^^^^^^^^^^^^^^^^^
  File "C:\Users\nhanh\AppData\Local\Programs\Python\Python312\Lib\site-packages\django\db\models\query.py", line 1493, in filter
    return self._filter_or_exclude(False, args, kwargs)
           ^^^^^^^^^^^^^^^^^^^^^^^^^^^^^^^^^^^^^^^^^^^^
  File "C:\Users\nhanh\AppData\Local\Programs\Python\Python312\Lib\site-packages\django\db\models\query.py", line 1511, in _filter_or_exclude
    clone._filter_or_exclude_inplace(negate, args, kwargs)
  File "C:\Users\nhanh\AppData\Local\Programs\Python\Python312\Lib\site-packages\django\db\models\query.py", line 1518, in _filter_or_exclude_inplace
    self._query.add_q(Q(*args, **kwargs))
  File "C:\Users\nhanh\AppData\Local\Programs\Python\Python312\Lib\site-packages\django\db\models\sql\query.py", line 1646, in add_q
    clause, _ = self._add_q(q_object, can_reuse)
                ^^^^^^^^^^^^^^^^^^^^^^^^^^^^^^^^
  File "C:\Users\nhanh\AppData\Local\Programs\Python\Python312\Lib\site-packages\django\db\models\sql\query.py", line 1678, in _add_q
    child_clause, needed_inner = self.build_filter(
                                 ^^^^^^^^^^^^^^^^^^
  File "C:\Users\nhanh\AppData\Local\Programs\Python\Python312\Lib\site-packages\django\db\models\sql\query.py", line 1588, in build_filter
    condition = self.build_lookup(lookups, col, value)
                ^^^^^^^^^^^^^^^^^^^^^^^^^^^^^^^^^^^^^^
  File "C:\Users\nhanh\AppData\Local\Programs\Python\Python312\Lib\site-packages\django\db\models\sql\query.py", line 1415, in build_lookup
    lookup = lookup_class(lhs, rhs)
             ^^^^^^^^^^^^^^^^^^^^^^
  File "C:\Users\nhanh\AppData\Local\Programs\Python\Python312\Lib\site-packages\django\db\models\lookups.py", line 38, in __init__
    self.rhs = self.get_prep_lookup()
               ^^^^^^^^^^^^^^^^^^^^^^
  File "C:\Users\nhanh\AppData\Local\Programs\Python\Python312\Lib\site-packages\django\db\models\fields\related_lookups.py", line 112, in get_prep_lookup
    self.rhs = target_field.get_prep_value(self.rhs)
               ^^^^^^^^^^^^^^^^^^^^^^^^^^^^^^^^^^^^^
  File "C:\Users\nhanh\AppData\Local\Programs\Python\Python312\Lib\site-packages\django\db\models\fields\__init__.py", line 2750, in get_prep_value
    return self.to_python(value)
           ^^^^^^^^^^^^^^^^^^^^^
  File "C:\Users\nhanh\AppData\Local\Programs\Python\Python312\Lib\site-packages\django\db\models\fields\__init__.py", line 2768, in to_python
    raise exceptions.ValidationError(
django.core.exceptions.ValidationError: ['“AnonymousUser” is not a valid UUID.']
WARNING 2025-08-01 08:45:47,402 base 25732 15668 view's PlanViewSet raised exception during schema generation; use `getattr(self, 'swagger_fake_view', False)` to detect and short-circuit this
Traceback (most recent call last):
  File "C:\Users\nhanh\AppData\Local\Programs\Python\Python312\Lib\site-packages\django\db\models\fields\__init__.py", line 2766, in to_python
    return uuid.UUID(**{input_form: value})
           ^^^^^^^^^^^^^^^^^^^^^^^^^^^^^^^^
  File "C:\Users\nhanh\AppData\Local\Programs\Python\Python312\Lib\uuid.py", line 175, in __init__
    hex = hex.replace('urn:', '').replace('uuid:', '')
          ^^^^^^^^^^^
AttributeError: 'AnonymousUser' object has no attribute 'replace'

During handling of the above exception, another exception occurred:

Traceback (most recent call last):
  File "C:\Users\nhanh\AppData\Local\Programs\Python\Python312\Lib\site-packages\drf_yasg\inspectors\base.py", line 42, in call_view_method
    return view_method()
           ^^^^^^^^^^^^^
  File "D:\Study\DoAnNganh\PlanPal\planpalapp\planpals\views.py", line 393, in get_queryset
    return Plan.objects.filter(
           ^^^^^^^^^^^^^^^^^^^^
  File "C:\Users\nhanh\AppData\Local\Programs\Python\Python312\Lib\site-packages\django\db\models\manager.py", line 87, in manager_method
    return getattr(self.get_queryset(), name)(*args, **kwargs)
           ^^^^^^^^^^^^^^^^^^^^^^^^^^^^^^^^^^^^^^^^^^^^^^^^^^^
  File "C:\Users\nhanh\AppData\Local\Programs\Python\Python312\Lib\site-packages\django\db\models\query.py", line 1493, in filter
    return self._filter_or_exclude(False, args, kwargs)
           ^^^^^^^^^^^^^^^^^^^^^^^^^^^^^^^^^^^^^^^^^^^^
  File "C:\Users\nhanh\AppData\Local\Programs\Python\Python312\Lib\site-packages\django\db\models\query.py", line 1511, in _filter_or_exclude
    clone._filter_or_exclude_inplace(negate, args, kwargs)
  File "C:\Users\nhanh\AppData\Local\Programs\Python\Python312\Lib\site-packages\django\db\models\query.py", line 1518, in _filter_or_exclude_inplace
    self._query.add_q(Q(*args, **kwargs))
  File "C:\Users\nhanh\AppData\Local\Programs\Python\Python312\Lib\site-packages\django\db\models\sql\query.py", line 1646, in add_q
    clause, _ = self._add_q(q_object, can_reuse)
                ^^^^^^^^^^^^^^^^^^^^^^^^^^^^^^^^
  File "C:\Users\nhanh\AppData\Local\Programs\Python\Python312\Lib\site-packages\django\db\models\sql\query.py", line 1678, in _add_q
    child_clause, needed_inner = self.build_filter(
                                 ^^^^^^^^^^^^^^^^^^
  File "C:\Users\nhanh\AppData\Local\Programs\Python\Python312\Lib\site-packages\django\db\models\sql\query.py", line 1503, in build_filter
    return self._add_q(
           ^^^^^^^^^^^^
  File "C:\Users\nhanh\AppData\Local\Programs\Python\Python312\Lib\site-packages\django\db\models\sql\query.py", line 1678, in _add_q
    child_clause, needed_inner = self.build_filter(
                                 ^^^^^^^^^^^^^^^^^^
  File "C:\Users\nhanh\AppData\Local\Programs\Python\Python312\Lib\site-packages\django\db\models\sql\query.py", line 1588, in build_filter
    condition = self.build_lookup(lookups, col, value)
                ^^^^^^^^^^^^^^^^^^^^^^^^^^^^^^^^^^^^^^
  File "C:\Users\nhanh\AppData\Local\Programs\Python\Python312\Lib\site-packages\django\db\models\sql\query.py", line 1415, in build_lookup
    lookup = lookup_class(lhs, rhs)
             ^^^^^^^^^^^^^^^^^^^^^^
  File "C:\Users\nhanh\AppData\Local\Programs\Python\Python312\Lib\site-packages\django\db\models\lookups.py", line 38, in __init__
    self.rhs = self.get_prep_lookup()
               ^^^^^^^^^^^^^^^^^^^^^^
  File "C:\Users\nhanh\AppData\Local\Programs\Python\Python312\Lib\site-packages\django\db\models\fields\related_lookups.py", line 112, in get_prep_lookup
    self.rhs = target_field.get_prep_value(self.rhs)
               ^^^^^^^^^^^^^^^^^^^^^^^^^^^^^^^^^^^^^
  File "C:\Users\nhanh\AppData\Local\Programs\Python\Python312\Lib\site-packages\django\db\models\fields\__init__.py", line 2750, in get_prep_value
    return self.to_python(value)
           ^^^^^^^^^^^^^^^^^^^^^
  File "C:\Users\nhanh\AppData\Local\Programs\Python\Python312\Lib\site-packages\django\db\models\fields\__init__.py", line 2768, in to_python
    raise exceptions.ValidationError(
django.core.exceptions.ValidationError: ['“AnonymousUser” is not a valid UUID.']
WARNING 2025-08-01 08:45:47,406 base 25732 15668 view's ChatMessageViewSet raised exception during schema generation; use `getattr(self, 'swagger_fake_view', False)` to detect and short-circuit this
Traceback (most recent call last):
  File "C:\Users\nhanh\AppData\Local\Programs\Python\Python312\Lib\site-packages\django\db\models\fields\__init__.py", line 2766, in to_python
    return uuid.UUID(**{input_form: value})
           ^^^^^^^^^^^^^^^^^^^^^^^^^^^^^^^^
  File "C:\Users\nhanh\AppData\Local\Programs\Python\Python312\Lib\uuid.py", line 175, in __init__
    hex = hex.replace('urn:', '').replace('uuid:', '')
          ^^^^^^^^^^^
AttributeError: 'AnonymousUser' object has no attribute 'replace'

During handling of the above exception, another exception occurred:

Traceback (most recent call last):
  File "C:\Users\nhanh\AppData\Local\Programs\Python\Python312\Lib\site-packages\drf_yasg\inspectors\base.py", line 42, in call_view_method
    return view_method()
           ^^^^^^^^^^^^^
  File "D:\Study\DoAnNganh\PlanPal\planpalapp\planpals\views.py", line 610, in get_queryset
    return ChatMessage.objects.filter(
           ^^^^^^^^^^^^^^^^^^^^^^^^^^^
  File "C:\Users\nhanh\AppData\Local\Programs\Python\Python312\Lib\site-packages\django\db\models\manager.py", line 87, in manager_method
    return getattr(self.get_queryset(), name)(*args, **kwargs)
           ^^^^^^^^^^^^^^^^^^^^^^^^^^^^^^^^^^^^^^^^^^^^^^^^^^^
  File "C:\Users\nhanh\AppData\Local\Programs\Python\Python312\Lib\site-packages\django\db\models\query.py", line 1493, in filter
    return self._filter_or_exclude(False, args, kwargs)
           ^^^^^^^^^^^^^^^^^^^^^^^^^^^^^^^^^^^^^^^^^^^^
  File "C:\Users\nhanh\AppData\Local\Programs\Python\Python312\Lib\site-packages\django\db\models\query.py", line 1511, in _filter_or_exclude
    clone._filter_or_exclude_inplace(negate, args, kwargs)
  File "C:\Users\nhanh\AppData\Local\Programs\Python\Python312\Lib\site-packages\django\db\models\query.py", line 1518, in _filter_or_exclude_inplace
    self._query.add_q(Q(*args, **kwargs))
  File "C:\Users\nhanh\AppData\Local\Programs\Python\Python312\Lib\site-packages\django\db\models\sql\query.py", line 1646, in add_q
    clause, _ = self._add_q(q_object, can_reuse)
                ^^^^^^^^^^^^^^^^^^^^^^^^^^^^^^^^
  File "C:\Users\nhanh\AppData\Local\Programs\Python\Python312\Lib\site-packages\django\db\models\sql\query.py", line 1678, in _add_q
    child_clause, needed_inner = self.build_filter(
                                 ^^^^^^^^^^^^^^^^^^
  File "C:\Users\nhanh\AppData\Local\Programs\Python\Python312\Lib\site-packages\django\db\models\sql\query.py", line 1588, in build_filter
    condition = self.build_lookup(lookups, col, value)
                ^^^^^^^^^^^^^^^^^^^^^^^^^^^^^^^^^^^^^^
  File "C:\Users\nhanh\AppData\Local\Programs\Python\Python312\Lib\site-packages\django\db\models\sql\query.py", line 1415, in build_lookup
    lookup = lookup_class(lhs, rhs)
             ^^^^^^^^^^^^^^^^^^^^^^
  File "C:\Users\nhanh\AppData\Local\Programs\Python\Python312\Lib\site-packages\django\db\models\lookups.py", line 38, in __init__
    self.rhs = self.get_prep_lookup()
               ^^^^^^^^^^^^^^^^^^^^^^
  File "C:\Users\nhanh\AppData\Local\Programs\Python\Python312\Lib\site-packages\django\db\models\fields\related_lookups.py", line 112, in get_prep_lookup
    self.rhs = target_field.get_prep_value(self.rhs)
               ^^^^^^^^^^^^^^^^^^^^^^^^^^^^^^^^^^^^^
  File "C:\Users\nhanh\AppData\Local\Programs\Python\Python312\Lib\site-packages\django\db\models\fields\__init__.py", line 2750, in get_prep_value
    return self.to_python(value)
           ^^^^^^^^^^^^^^^^^^^^^
  File "C:\Users\nhanh\AppData\Local\Programs\Python\Python312\Lib\site-packages\django\db\models\fields\__init__.py", line 2768, in to_python
    raise exceptions.ValidationError(
django.core.exceptions.ValidationError: ['“AnonymousUser” is not a valid UUID.']
WARNING 2025-08-01 08:45:47,418 base 25732 15668 view's PlanActivityViewSet raised exception during schema generation; use `getattr(self, 'swagger_fake_view', False)` to detect and short-circuit this
Traceback (most recent call last):
  File "C:\Users\nhanh\AppData\Local\Programs\Python\Python312\Lib\site-packages\django\db\models\fields\__init__.py", line 2766, in to_python
    return uuid.UUID(**{input_form: value})
           ^^^^^^^^^^^^^^^^^^^^^^^^^^^^^^^^
  File "C:\Users\nhanh\AppData\Local\Programs\Python\Python312\Lib\uuid.py", line 175, in __init__
    hex = hex.replace('urn:', '').replace('uuid:', '')
          ^^^^^^^^^^^
AttributeError: 'AnonymousUser' object has no attribute 'replace'

During handling of the above exception, another exception occurred:

Traceback (most recent call last):
  File "C:\Users\nhanh\AppData\Local\Programs\Python\Python312\Lib\site-packages\drf_yasg\inspectors\base.py", line 42, in call_view_method
    return view_method()
           ^^^^^^^^^^^^^
  File "D:\Study\DoAnNganh\PlanPal\planpalapp\planpals\views.py", line 805, in get_queryset
    return PlanActivity.objects.filter(
           ^^^^^^^^^^^^^^^^^^^^^^^^^^^^
  File "C:\Users\nhanh\AppData\Local\Programs\Python\Python312\Lib\site-packages\django\db\models\manager.py", line 87, in manager_method
    return getattr(self.get_queryset(), name)(*args, **kwargs)
           ^^^^^^^^^^^^^^^^^^^^^^^^^^^^^^^^^^^^^^^^^^^^^^^^^^^
  File "C:\Users\nhanh\AppData\Local\Programs\Python\Python312\Lib\site-packages\django\db\models\query.py", line 1493, in filter
    return self._filter_or_exclude(False, args, kwargs)
           ^^^^^^^^^^^^^^^^^^^^^^^^^^^^^^^^^^^^^^^^^^^^
  File "C:\Users\nhanh\AppData\Local\Programs\Python\Python312\Lib\site-packages\django\db\models\query.py", line 1511, in _filter_or_exclude
    clone._filter_or_exclude_inplace(negate, args, kwargs)
  File "C:\Users\nhanh\AppData\Local\Programs\Python\Python312\Lib\site-packages\django\db\models\query.py", line 1518, in _filter_or_exclude_inplace
    self._query.add_q(Q(*args, **kwargs))
  File "C:\Users\nhanh\AppData\Local\Programs\Python\Python312\Lib\site-packages\django\db\models\sql\query.py", line 1646, in add_q
    clause, _ = self._add_q(q_object, can_reuse)
                ^^^^^^^^^^^^^^^^^^^^^^^^^^^^^^^^
  File "C:\Users\nhanh\AppData\Local\Programs\Python\Python312\Lib\site-packages\django\db\models\sql\query.py", line 1678, in _add_q
    child_clause, needed_inner = self.build_filter(
                                 ^^^^^^^^^^^^^^^^^^
  File "C:\Users\nhanh\AppData\Local\Programs\Python\Python312\Lib\site-packages\django\db\models\sql\query.py", line 1588, in build_filter
    condition = self.build_lookup(lookups, col, value)
                ^^^^^^^^^^^^^^^^^^^^^^^^^^^^^^^^^^^^^^
  File "C:\Users\nhanh\AppData\Local\Programs\Python\Python312\Lib\site-packages\django\db\models\sql\query.py", line 1415, in build_lookup
    lookup = lookup_class(lhs, rhs)
             ^^^^^^^^^^^^^^^^^^^^^^
  File "C:\Users\nhanh\AppData\Local\Programs\Python\Python312\Lib\site-packages\django\db\models\lookups.py", line 38, in __init__
    self.rhs = self.get_prep_lookup()
               ^^^^^^^^^^^^^^^^^^^^^^
  File "C:\Users\nhanh\AppData\Local\Programs\Python\Python312\Lib\site-packages\django\db\models\fields\related_lookups.py", line 112, in get_prep_lookup
    self.rhs = target_field.get_prep_value(self.rhs)
               ^^^^^^^^^^^^^^^^^^^^^^^^^^^^^^^^^^^^^
  File "C:\Users\nhanh\AppData\Local\Programs\Python\Python312\Lib\site-packages\django\db\models\fields\__init__.py", line 2750, in get_prep_value
    return self.to_python(value)
           ^^^^^^^^^^^^^^^^^^^^^
  File "C:\Users\nhanh\AppData\Local\Programs\Python\Python312\Lib\site-packages\django\db\models\fields\__init__.py", line 2768, in to_python
    raise exceptions.ValidationError(
django.core.exceptions.ValidationError: ['“AnonymousUser” is not a valid UUID.']
WARNING 2025-08-01 08:45:47,421 base 25732 15668 view's GroupViewSet raised exception during schema generation; use `getattr(self, 'swagger_fake_view', False)` to detect and short-circuit this
Traceback (most recent call last):
  File "C:\Users\nhanh\AppData\Local\Programs\Python\Python312\Lib\site-packages\django\db\models\fields\__init__.py", line 2766, in to_python
    return uuid.UUID(**{input_form: value})
           ^^^^^^^^^^^^^^^^^^^^^^^^^^^^^^^^
  File "C:\Users\nhanh\AppData\Local\Programs\Python\Python312\Lib\uuid.py", line 175, in __init__
    hex = hex.replace('urn:', '').replace('uuid:', '')
          ^^^^^^^^^^^
AttributeError: 'AnonymousUser' object has no attribute 'replace'

During handling of the above exception, another exception occurred:

Traceback (most recent call last):
  File "C:\Users\nhanh\AppData\Local\Programs\Python\Python312\Lib\site-packages\drf_yasg\inspectors\base.py", line 42, in call_view_method
    return view_method()
           ^^^^^^^^^^^^^
  File "D:\Study\DoAnNganh\PlanPal\planpalapp\planpals\views.py", line 232, in get_queryset
    return Group.objects.filter(
           ^^^^^^^^^^^^^^^^^^^^^
  File "C:\Users\nhanh\AppData\Local\Programs\Python\Python312\Lib\site-packages\django\db\models\manager.py", line 87, in manager_method
    return getattr(self.get_queryset(), name)(*args, **kwargs)
           ^^^^^^^^^^^^^^^^^^^^^^^^^^^^^^^^^^^^^^^^^^^^^^^^^^^
  File "C:\Users\nhanh\AppData\Local\Programs\Python\Python312\Lib\site-packages\django\db\models\query.py", line 1493, in filter
    return self._filter_or_exclude(False, args, kwargs)
           ^^^^^^^^^^^^^^^^^^^^^^^^^^^^^^^^^^^^^^^^^^^^
  File "C:\Users\nhanh\AppData\Local\Programs\Python\Python312\Lib\site-packages\django\db\models\query.py", line 1511, in _filter_or_exclude
    clone._filter_or_exclude_inplace(negate, args, kwargs)
  File "C:\Users\nhanh\AppData\Local\Programs\Python\Python312\Lib\site-packages\django\db\models\query.py", line 1518, in _filter_or_exclude_inplace
    self._query.add_q(Q(*args, **kwargs))
  File "C:\Users\nhanh\AppData\Local\Programs\Python\Python312\Lib\site-packages\django\db\models\sql\query.py", line 1646, in add_q
    clause, _ = self._add_q(q_object, can_reuse)
                ^^^^^^^^^^^^^^^^^^^^^^^^^^^^^^^^
  File "C:\Users\nhanh\AppData\Local\Programs\Python\Python312\Lib\site-packages\django\db\models\sql\query.py", line 1678, in _add_q
    child_clause, needed_inner = self.build_filter(
                                 ^^^^^^^^^^^^^^^^^^
  File "C:\Users\nhanh\AppData\Local\Programs\Python\Python312\Lib\site-packages\django\db\models\sql\query.py", line 1588, in build_filter
    condition = self.build_lookup(lookups, col, value)
                ^^^^^^^^^^^^^^^^^^^^^^^^^^^^^^^^^^^^^^
  File "C:\Users\nhanh\AppData\Local\Programs\Python\Python312\Lib\site-packages\django\db\models\sql\query.py", line 1415, in build_lookup
    lookup = lookup_class(lhs, rhs)
             ^^^^^^^^^^^^^^^^^^^^^^
  File "C:\Users\nhanh\AppData\Local\Programs\Python\Python312\Lib\site-packages\django\db\models\lookups.py", line 38, in __init__
    self.rhs = self.get_prep_lookup()
               ^^^^^^^^^^^^^^^^^^^^^^
  File "C:\Users\nhanh\AppData\Local\Programs\Python\Python312\Lib\site-packages\django\db\models\fields\related_lookups.py", line 112, in get_prep_lookup
    self.rhs = target_field.get_prep_value(self.rhs)
               ^^^^^^^^^^^^^^^^^^^^^^^^^^^^^^^^^^^^^
  File "C:\Users\nhanh\AppData\Local\Programs\Python\Python312\Lib\site-packages\django\db\models\fields\__init__.py", line 2750, in get_prep_value
    return self.to_python(value)
           ^^^^^^^^^^^^^^^^^^^^^
  File "C:\Users\nhanh\AppData\Local\Programs\Python\Python312\Lib\site-packages\django\db\models\fields\__init__.py", line 2768, in to_python
    raise exceptions.ValidationError(
django.core.exceptions.ValidationError: ['“AnonymousUser” is not a valid UUID.']
WARNING 2025-08-01 08:45:47,427 base 25732 15668 view's PlanViewSet raised exception during schema generation; use `getattr(self, 'swagger_fake_view', False)` to detect and short-circuit this
Traceback (most recent call last):
  File "C:\Users\nhanh\AppData\Local\Programs\Python\Python312\Lib\site-packages\django\db\models\fields\__init__.py", line 2766, in to_python
    return uuid.UUID(**{input_form: value})
           ^^^^^^^^^^^^^^^^^^^^^^^^^^^^^^^^
  File "C:\Users\nhanh\AppData\Local\Programs\Python\Python312\Lib\uuid.py", line 175, in __init__
    hex = hex.replace('urn:', '').replace('uuid:', '')
          ^^^^^^^^^^^
AttributeError: 'AnonymousUser' object has no attribute 'replace'

During handling of the above exception, another exception occurred:

Traceback (most recent call last):
  File "C:\Users\nhanh\AppData\Local\Programs\Python\Python312\Lib\site-packages\drf_yasg\inspectors\base.py", line 42, in call_view_method
    return view_method()
           ^^^^^^^^^^^^^
  File "D:\Study\DoAnNganh\PlanPal\planpalapp\planpals\views.py", line 393, in get_queryset
    return Plan.objects.filter(
           ^^^^^^^^^^^^^^^^^^^^
  File "C:\Users\nhanh\AppData\Local\Programs\Python\Python312\Lib\site-packages\django\db\models\manager.py", line 87, in manager_method
    return getattr(self.get_queryset(), name)(*args, **kwargs)
           ^^^^^^^^^^^^^^^^^^^^^^^^^^^^^^^^^^^^^^^^^^^^^^^^^^^
  File "C:\Users\nhanh\AppData\Local\Programs\Python\Python312\Lib\site-packages\django\db\models\query.py", line 1493, in filter
    return self._filter_or_exclude(False, args, kwargs)
           ^^^^^^^^^^^^^^^^^^^^^^^^^^^^^^^^^^^^^^^^^^^^
  File "C:\Users\nhanh\AppData\Local\Programs\Python\Python312\Lib\site-packages\django\db\models\query.py", line 1511, in _filter_or_exclude
    clone._filter_or_exclude_inplace(negate, args, kwargs)
  File "C:\Users\nhanh\AppData\Local\Programs\Python\Python312\Lib\site-packages\django\db\models\query.py", line 1518, in _filter_or_exclude_inplace
    self._query.add_q(Q(*args, **kwargs))
  File "C:\Users\nhanh\AppData\Local\Programs\Python\Python312\Lib\site-packages\django\db\models\sql\query.py", line 1646, in add_q
    clause, _ = self._add_q(q_object, can_reuse)
                ^^^^^^^^^^^^^^^^^^^^^^^^^^^^^^^^
  File "C:\Users\nhanh\AppData\Local\Programs\Python\Python312\Lib\site-packages\django\db\models\sql\query.py", line 1678, in _add_q
    child_clause, needed_inner = self.build_filter(
                                 ^^^^^^^^^^^^^^^^^^
  File "C:\Users\nhanh\AppData\Local\Programs\Python\Python312\Lib\site-packages\django\db\models\sql\query.py", line 1503, in build_filter
    return self._add_q(
           ^^^^^^^^^^^^
  File "C:\Users\nhanh\AppData\Local\Programs\Python\Python312\Lib\site-packages\django\db\models\sql\query.py", line 1678, in _add_q
    child_clause, needed_inner = self.build_filter(
                                 ^^^^^^^^^^^^^^^^^^
  File "C:\Users\nhanh\AppData\Local\Programs\Python\Python312\Lib\site-packages\django\db\models\sql\query.py", line 1588, in build_filter
    condition = self.build_lookup(lookups, col, value)
                ^^^^^^^^^^^^^^^^^^^^^^^^^^^^^^^^^^^^^^
  File "C:\Users\nhanh\AppData\Local\Programs\Python\Python312\Lib\site-packages\django\db\models\sql\query.py", line 1415, in build_lookup
    lookup = lookup_class(lhs, rhs)
             ^^^^^^^^^^^^^^^^^^^^^^
  File "C:\Users\nhanh\AppData\Local\Programs\Python\Python312\Lib\site-packages\django\db\models\lookups.py", line 38, in __init__
    self.rhs = self.get_prep_lookup()
               ^^^^^^^^^^^^^^^^^^^^^^
  File "C:\Users\nhanh\AppData\Local\Programs\Python\Python312\Lib\site-packages\django\db\models\fields\related_lookups.py", line 112, in get_prep_lookup
    self.rhs = target_field.get_prep_value(self.rhs)
               ^^^^^^^^^^^^^^^^^^^^^^^^^^^^^^^^^^^^^
  File "C:\Users\nhanh\AppData\Local\Programs\Python\Python312\Lib\site-packages\django\db\models\fields\__init__.py", line 2750, in get_prep_value
    return self.to_python(value)
           ^^^^^^^^^^^^^^^^^^^^^
  File "C:\Users\nhanh\AppData\Local\Programs\Python\Python312\Lib\site-packages\django\db\models\fields\__init__.py", line 2768, in to_python
    raise exceptions.ValidationError(
django.core.exceptions.ValidationError: ['“AnonymousUser” is not a valid UUID.']
WARNING 2025-08-01 08:45:47,433 base 25732 15668 view's ChatMessageViewSet raised exception during schema generation; use `getattr(self, 'swagger_fake_view', False)` to detect and short-circuit this
Traceback (most recent call last):
  File "C:\Users\nhanh\AppData\Local\Programs\Python\Python312\Lib\site-packages\django\db\models\fields\__init__.py", line 2766, in to_python
    return uuid.UUID(**{input_form: value})
           ^^^^^^^^^^^^^^^^^^^^^^^^^^^^^^^^
  File "C:\Users\nhanh\AppData\Local\Programs\Python\Python312\Lib\uuid.py", line 175, in __init__
    hex = hex.replace('urn:', '').replace('uuid:', '')
          ^^^^^^^^^^^
AttributeError: 'AnonymousUser' object has no attribute 'replace'

During handling of the above exception, another exception occurred:

Traceback (most recent call last):
  File "C:\Users\nhanh\AppData\Local\Programs\Python\Python312\Lib\site-packages\drf_yasg\inspectors\base.py", line 42, in call_view_method
    return view_method()
           ^^^^^^^^^^^^^
  File "D:\Study\DoAnNganh\PlanPal\planpalapp\planpals\views.py", line 610, in get_queryset
    return ChatMessage.objects.filter(
           ^^^^^^^^^^^^^^^^^^^^^^^^^^^
  File "C:\Users\nhanh\AppData\Local\Programs\Python\Python312\Lib\site-packages\django\db\models\manager.py", line 87, in manager_method
    return getattr(self.get_queryset(), name)(*args, **kwargs)
           ^^^^^^^^^^^^^^^^^^^^^^^^^^^^^^^^^^^^^^^^^^^^^^^^^^^
  File "C:\Users\nhanh\AppData\Local\Programs\Python\Python312\Lib\site-packages\django\db\models\query.py", line 1493, in filter
    return self._filter_or_exclude(False, args, kwargs)
           ^^^^^^^^^^^^^^^^^^^^^^^^^^^^^^^^^^^^^^^^^^^^
  File "C:\Users\nhanh\AppData\Local\Programs\Python\Python312\Lib\site-packages\django\db\models\query.py", line 1511, in _filter_or_exclude
    clone._filter_or_exclude_inplace(negate, args, kwargs)
  File "C:\Users\nhanh\AppData\Local\Programs\Python\Python312\Lib\site-packages\django\db\models\query.py", line 1518, in _filter_or_exclude_inplace
    self._query.add_q(Q(*args, **kwargs))
  File "C:\Users\nhanh\AppData\Local\Programs\Python\Python312\Lib\site-packages\django\db\models\sql\query.py", line 1646, in add_q
    clause, _ = self._add_q(q_object, can_reuse)
                ^^^^^^^^^^^^^^^^^^^^^^^^^^^^^^^^
  File "C:\Users\nhanh\AppData\Local\Programs\Python\Python312\Lib\site-packages\django\db\models\sql\query.py", line 1678, in _add_q
    child_clause, needed_inner = self.build_filter(
                                 ^^^^^^^^^^^^^^^^^^
  File "C:\Users\nhanh\AppData\Local\Programs\Python\Python312\Lib\site-packages\django\db\models\sql\query.py", line 1588, in build_filter
    condition = self.build_lookup(lookups, col, value)
                ^^^^^^^^^^^^^^^^^^^^^^^^^^^^^^^^^^^^^^
  File "C:\Users\nhanh\AppData\Local\Programs\Python\Python312\Lib\site-packages\django\db\models\sql\query.py", line 1415, in build_lookup
    lookup = lookup_class(lhs, rhs)
             ^^^^^^^^^^^^^^^^^^^^^^
  File "C:\Users\nhanh\AppData\Local\Programs\Python\Python312\Lib\site-packages\django\db\models\lookups.py", line 38, in __init__
    self.rhs = self.get_prep_lookup()
               ^^^^^^^^^^^^^^^^^^^^^^
  File "C:\Users\nhanh\AppData\Local\Programs\Python\Python312\Lib\site-packages\django\db\models\fields\related_lookups.py", line 112, in get_prep_lookup
    self.rhs = target_field.get_prep_value(self.rhs)
               ^^^^^^^^^^^^^^^^^^^^^^^^^^^^^^^^^^^^^
  File "C:\Users\nhanh\AppData\Local\Programs\Python\Python312\Lib\site-packages\django\db\models\fields\__init__.py", line 2750, in get_prep_value
    return self.to_python(value)
           ^^^^^^^^^^^^^^^^^^^^^
  File "C:\Users\nhanh\AppData\Local\Programs\Python\Python312\Lib\site-packages\django\db\models\fields\__init__.py", line 2768, in to_python
    raise exceptions.ValidationError(
django.core.exceptions.ValidationError: ['“AnonymousUser” is not a valid UUID.']
WARNING 2025-08-01 08:45:47,438 base 25732 15668 view's PlanActivityViewSet raised exception during schema generation; use `getattr(self, 'swagger_fake_view', False)` to detect and short-circuit this
Traceback (most recent call last):
  File "C:\Users\nhanh\AppData\Local\Programs\Python\Python312\Lib\site-packages\django\db\models\fields\__init__.py", line 2766, in to_python
    return uuid.UUID(**{input_form: value})
           ^^^^^^^^^^^^^^^^^^^^^^^^^^^^^^^^
  File "C:\Users\nhanh\AppData\Local\Programs\Python\Python312\Lib\uuid.py", line 175, in __init__
    hex = hex.replace('urn:', '').replace('uuid:', '')
          ^^^^^^^^^^^
AttributeError: 'AnonymousUser' object has no attribute 'replace'

During handling of the above exception, another exception occurred:

Traceback (most recent call last):
  File "C:\Users\nhanh\AppData\Local\Programs\Python\Python312\Lib\site-packages\drf_yasg\inspectors\base.py", line 42, in call_view_method
    return view_method()
           ^^^^^^^^^^^^^
  File "D:\Study\DoAnNganh\PlanPal\planpalapp\planpals\views.py", line 805, in get_queryset
    return PlanActivity.objects.filter(
           ^^^^^^^^^^^^^^^^^^^^^^^^^^^^
  File "C:\Users\nhanh\AppData\Local\Programs\Python\Python312\Lib\site-packages\django\db\models\manager.py", line 87, in manager_method
    return getattr(self.get_queryset(), name)(*args, **kwargs)
           ^^^^^^^^^^^^^^^^^^^^^^^^^^^^^^^^^^^^^^^^^^^^^^^^^^^
  File "C:\Users\nhanh\AppData\Local\Programs\Python\Python312\Lib\site-packages\django\db\models\query.py", line 1493, in filter
    return self._filter_or_exclude(False, args, kwargs)
           ^^^^^^^^^^^^^^^^^^^^^^^^^^^^^^^^^^^^^^^^^^^^
  File "C:\Users\nhanh\AppData\Local\Programs\Python\Python312\Lib\site-packages\django\db\models\query.py", line 1511, in _filter_or_exclude
    clone._filter_or_exclude_inplace(negate, args, kwargs)
  File "C:\Users\nhanh\AppData\Local\Programs\Python\Python312\Lib\site-packages\django\db\models\query.py", line 1518, in _filter_or_exclude_inplace
    self._query.add_q(Q(*args, **kwargs))
  File "C:\Users\nhanh\AppData\Local\Programs\Python\Python312\Lib\site-packages\django\db\models\sql\query.py", line 1646, in add_q
    clause, _ = self._add_q(q_object, can_reuse)
                ^^^^^^^^^^^^^^^^^^^^^^^^^^^^^^^^
  File "C:\Users\nhanh\AppData\Local\Programs\Python\Python312\Lib\site-packages\django\db\models\sql\query.py", line 1678, in _add_q
    child_clause, needed_inner = self.build_filter(
                                 ^^^^^^^^^^^^^^^^^^
  File "C:\Users\nhanh\AppData\Local\Programs\Python\Python312\Lib\site-packages\django\db\models\sql\query.py", line 1588, in build_filter
    condition = self.build_lookup(lookups, col, value)
                ^^^^^^^^^^^^^^^^^^^^^^^^^^^^^^^^^^^^^^
  File "C:\Users\nhanh\AppData\Local\Programs\Python\Python312\Lib\site-packages\django\db\models\sql\query.py", line 1415, in build_lookup
    lookup = lookup_class(lhs, rhs)
             ^^^^^^^^^^^^^^^^^^^^^^
  File "C:\Users\nhanh\AppData\Local\Programs\Python\Python312\Lib\site-packages\django\db\models\lookups.py", line 38, in __init__
    self.rhs = self.get_prep_lookup()
               ^^^^^^^^^^^^^^^^^^^^^^
  File "C:\Users\nhanh\AppData\Local\Programs\Python\Python312\Lib\site-packages\django\db\models\fields\related_lookups.py", line 112, in get_prep_lookup
    self.rhs = target_field.get_prep_value(self.rhs)
               ^^^^^^^^^^^^^^^^^^^^^^^^^^^^^^^^^^^^^
  File "C:\Users\nhanh\AppData\Local\Programs\Python\Python312\Lib\site-packages\django\db\models\fields\__init__.py", line 2750, in get_prep_value
    return self.to_python(value)
           ^^^^^^^^^^^^^^^^^^^^^
  File "C:\Users\nhanh\AppData\Local\Programs\Python\Python312\Lib\site-packages\django\db\models\fields\__init__.py", line 2768, in to_python
    raise exceptions.ValidationError(
django.core.exceptions.ValidationError: ['“AnonymousUser” is not a valid UUID.']
WARNING 2025-08-01 08:45:47,443 base 25732 15668 view's GroupViewSet raised exception during schema generation; use `getattr(self, 'swagger_fake_view', False)` to detect and short-circuit this
Traceback (most recent call last):
  File "C:\Users\nhanh\AppData\Local\Programs\Python\Python312\Lib\site-packages\django\db\models\fields\__init__.py", line 2766, in to_python
    return uuid.UUID(**{input_form: value})
           ^^^^^^^^^^^^^^^^^^^^^^^^^^^^^^^^
  File "C:\Users\nhanh\AppData\Local\Programs\Python\Python312\Lib\uuid.py", line 175, in __init__
    hex = hex.replace('urn:', '').replace('uuid:', '')
          ^^^^^^^^^^^
AttributeError: 'AnonymousUser' object has no attribute 'replace'

During handling of the above exception, another exception occurred:

Traceback (most recent call last):
  File "C:\Users\nhanh\AppData\Local\Programs\Python\Python312\Lib\site-packages\drf_yasg\inspectors\base.py", line 42, in call_view_method
    return view_method()
           ^^^^^^^^^^^^^
  File "D:\Study\DoAnNganh\PlanPal\planpalapp\planpals\views.py", line 232, in get_queryset
    return Group.objects.filter(
           ^^^^^^^^^^^^^^^^^^^^^
  File "C:\Users\nhanh\AppData\Local\Programs\Python\Python312\Lib\site-packages\django\db\models\manager.py", line 87, in manager_method
    return getattr(self.get_queryset(), name)(*args, **kwargs)
           ^^^^^^^^^^^^^^^^^^^^^^^^^^^^^^^^^^^^^^^^^^^^^^^^^^^
  File "C:\Users\nhanh\AppData\Local\Programs\Python\Python312\Lib\site-packages\django\db\models\query.py", line 1493, in filter
    return self._filter_or_exclude(False, args, kwargs)
           ^^^^^^^^^^^^^^^^^^^^^^^^^^^^^^^^^^^^^^^^^^^^
  File "C:\Users\nhanh\AppData\Local\Programs\Python\Python312\Lib\site-packages\django\db\models\query.py", line 1511, in _filter_or_exclude
    clone._filter_or_exclude_inplace(negate, args, kwargs)
  File "C:\Users\nhanh\AppData\Local\Programs\Python\Python312\Lib\site-packages\django\db\models\query.py", line 1518, in _filter_or_exclude_inplace
    self._query.add_q(Q(*args, **kwargs))
  File "C:\Users\nhanh\AppData\Local\Programs\Python\Python312\Lib\site-packages\django\db\models\sql\query.py", line 1646, in add_q
    clause, _ = self._add_q(q_object, can_reuse)
                ^^^^^^^^^^^^^^^^^^^^^^^^^^^^^^^^
  File "C:\Users\nhanh\AppData\Local\Programs\Python\Python312\Lib\site-packages\django\db\models\sql\query.py", line 1678, in _add_q
    child_clause, needed_inner = self.build_filter(
                                 ^^^^^^^^^^^^^^^^^^
  File "C:\Users\nhanh\AppData\Local\Programs\Python\Python312\Lib\site-packages\django\db\models\sql\query.py", line 1588, in build_filter
    condition = self.build_lookup(lookups, col, value)
                ^^^^^^^^^^^^^^^^^^^^^^^^^^^^^^^^^^^^^^
  File "C:\Users\nhanh\AppData\Local\Programs\Python\Python312\Lib\site-packages\django\db\models\sql\query.py", line 1415, in build_lookup
    lookup = lookup_class(lhs, rhs)
             ^^^^^^^^^^^^^^^^^^^^^^
  File "C:\Users\nhanh\AppData\Local\Programs\Python\Python312\Lib\site-packages\django\db\models\lookups.py", line 38, in __init__
    self.rhs = self.get_prep_lookup()
               ^^^^^^^^^^^^^^^^^^^^^^
  File "C:\Users\nhanh\AppData\Local\Programs\Python\Python312\Lib\site-packages\django\db\models\fields\related_lookups.py", line 112, in get_prep_lookup
    self.rhs = target_field.get_prep_value(self.rhs)
               ^^^^^^^^^^^^^^^^^^^^^^^^^^^^^^^^^^^^^
  File "C:\Users\nhanh\AppData\Local\Programs\Python\Python312\Lib\site-packages\django\db\models\fields\__init__.py", line 2750, in get_prep_value
    return self.to_python(value)
           ^^^^^^^^^^^^^^^^^^^^^
  File "C:\Users\nhanh\AppData\Local\Programs\Python\Python312\Lib\site-packages\django\db\models\fields\__init__.py", line 2768, in to_python
    raise exceptions.ValidationError(
django.core.exceptions.ValidationError: ['“AnonymousUser” is not a valid UUID.']
WARNING 2025-08-01 08:45:47,446 base 25732 15668 view's PlanViewSet raised exception during schema generation; use `getattr(self, 'swagger_fake_view', False)` to detect and short-circuit this
Traceback (most recent call last):
  File "C:\Users\nhanh\AppData\Local\Programs\Python\Python312\Lib\site-packages\django\db\models\fields\__init__.py", line 2766, in to_python
    return uuid.UUID(**{input_form: value})
           ^^^^^^^^^^^^^^^^^^^^^^^^^^^^^^^^
  File "C:\Users\nhanh\AppData\Local\Programs\Python\Python312\Lib\uuid.py", line 175, in __init__
    hex = hex.replace('urn:', '').replace('uuid:', '')
          ^^^^^^^^^^^
AttributeError: 'AnonymousUser' object has no attribute 'replace'

During handling of the above exception, another exception occurred:

Traceback (most recent call last):
  File "C:\Users\nhanh\AppData\Local\Programs\Python\Python312\Lib\site-packages\drf_yasg\inspectors\base.py", line 42, in call_view_method
    return view_method()
           ^^^^^^^^^^^^^
  File "D:\Study\DoAnNganh\PlanPal\planpalapp\planpals\views.py", line 393, in get_queryset
    return Plan.objects.filter(
           ^^^^^^^^^^^^^^^^^^^^
  File "C:\Users\nhanh\AppData\Local\Programs\Python\Python312\Lib\site-packages\django\db\models\manager.py", line 87, in manager_method
    return getattr(self.get_queryset(), name)(*args, **kwargs)
           ^^^^^^^^^^^^^^^^^^^^^^^^^^^^^^^^^^^^^^^^^^^^^^^^^^^
  File "C:\Users\nhanh\AppData\Local\Programs\Python\Python312\Lib\site-packages\django\db\models\query.py", line 1493, in filter
    return self._filter_or_exclude(False, args, kwargs)
           ^^^^^^^^^^^^^^^^^^^^^^^^^^^^^^^^^^^^^^^^^^^^
  File "C:\Users\nhanh\AppData\Local\Programs\Python\Python312\Lib\site-packages\django\db\models\query.py", line 1511, in _filter_or_exclude
    clone._filter_or_exclude_inplace(negate, args, kwargs)
  File "C:\Users\nhanh\AppData\Local\Programs\Python\Python312\Lib\site-packages\django\db\models\query.py", line 1518, in _filter_or_exclude_inplace
    self._query.add_q(Q(*args, **kwargs))
  File "C:\Users\nhanh\AppData\Local\Programs\Python\Python312\Lib\site-packages\django\db\models\sql\query.py", line 1646, in add_q
    clause, _ = self._add_q(q_object, can_reuse)
                ^^^^^^^^^^^^^^^^^^^^^^^^^^^^^^^^
  File "C:\Users\nhanh\AppData\Local\Programs\Python\Python312\Lib\site-packages\django\db\models\sql\query.py", line 1678, in _add_q
    child_clause, needed_inner = self.build_filter(
                                 ^^^^^^^^^^^^^^^^^^
  File "C:\Users\nhanh\AppData\Local\Programs\Python\Python312\Lib\site-packages\django\db\models\sql\query.py", line 1503, in build_filter
    return self._add_q(
           ^^^^^^^^^^^^
  File "C:\Users\nhanh\AppData\Local\Programs\Python\Python312\Lib\site-packages\django\db\models\sql\query.py", line 1678, in _add_q
    child_clause, needed_inner = self.build_filter(
                                 ^^^^^^^^^^^^^^^^^^
  File "C:\Users\nhanh\AppData\Local\Programs\Python\Python312\Lib\site-packages\django\db\models\sql\query.py", line 1588, in build_filter
    condition = self.build_lookup(lookups, col, value)
                ^^^^^^^^^^^^^^^^^^^^^^^^^^^^^^^^^^^^^^
  File "C:\Users\nhanh\AppData\Local\Programs\Python\Python312\Lib\site-packages\django\db\models\sql\query.py", line 1415, in build_lookup
    lookup = lookup_class(lhs, rhs)
             ^^^^^^^^^^^^^^^^^^^^^^
  File "C:\Users\nhanh\AppData\Local\Programs\Python\Python312\Lib\site-packages\django\db\models\lookups.py", line 38, in __init__
    self.rhs = self.get_prep_lookup()
               ^^^^^^^^^^^^^^^^^^^^^^
  File "C:\Users\nhanh\AppData\Local\Programs\Python\Python312\Lib\site-packages\django\db\models\fields\related_lookups.py", line 112, in get_prep_lookup
    self.rhs = target_field.get_prep_value(self.rhs)
               ^^^^^^^^^^^^^^^^^^^^^^^^^^^^^^^^^^^^^
  File "C:\Users\nhanh\AppData\Local\Programs\Python\Python312\Lib\site-packages\django\db\models\fields\__init__.py", line 2750, in get_prep_value
    return self.to_python(value)
           ^^^^^^^^^^^^^^^^^^^^^
  File "C:\Users\nhanh\AppData\Local\Programs\Python\Python312\Lib\site-packages\django\db\models\fields\__init__.py", line 2768, in to_python
    raise exceptions.ValidationError(
django.core.exceptions.ValidationError: ['“AnonymousUser” is not a valid UUID.']
WARNING 2025-08-01 08:45:47,451 base 25732 15668 view's ChatMessageViewSet raised exception during schema generation; use `getattr(self, 'swagger_fake_view', False)` to detect and short-circuit this
Traceback (most recent call last):
  File "C:\Users\nhanh\AppData\Local\Programs\Python\Python312\Lib\site-packages\django\db\models\fields\__init__.py", line 2766, in to_python
    return uuid.UUID(**{input_form: value})
           ^^^^^^^^^^^^^^^^^^^^^^^^^^^^^^^^
  File "C:\Users\nhanh\AppData\Local\Programs\Python\Python312\Lib\uuid.py", line 175, in __init__
    hex = hex.replace('urn:', '').replace('uuid:', '')
          ^^^^^^^^^^^
AttributeError: 'AnonymousUser' object has no attribute 'replace'

During handling of the above exception, another exception occurred:

Traceback (most recent call last):
  File "C:\Users\nhanh\AppData\Local\Programs\Python\Python312\Lib\site-packages\drf_yasg\inspectors\base.py", line 42, in call_view_method
    return view_method()
           ^^^^^^^^^^^^^
  File "D:\Study\DoAnNganh\PlanPal\planpalapp\planpals\views.py", line 610, in get_queryset
    return ChatMessage.objects.filter(
           ^^^^^^^^^^^^^^^^^^^^^^^^^^^
  File "C:\Users\nhanh\AppData\Local\Programs\Python\Python312\Lib\site-packages\django\db\models\manager.py", line 87, in manager_method
    return getattr(self.get_queryset(), name)(*args, **kwargs)
           ^^^^^^^^^^^^^^^^^^^^^^^^^^^^^^^^^^^^^^^^^^^^^^^^^^^
  File "C:\Users\nhanh\AppData\Local\Programs\Python\Python312\Lib\site-packages\django\db\models\query.py", line 1493, in filter
    return self._filter_or_exclude(False, args, kwargs)
           ^^^^^^^^^^^^^^^^^^^^^^^^^^^^^^^^^^^^^^^^^^^^
  File "C:\Users\nhanh\AppData\Local\Programs\Python\Python312\Lib\site-packages\django\db\models\query.py", line 1511, in _filter_or_exclude
    clone._filter_or_exclude_inplace(negate, args, kwargs)
  File "C:\Users\nhanh\AppData\Local\Programs\Python\Python312\Lib\site-packages\django\db\models\query.py", line 1518, in _filter_or_exclude_inplace
    self._query.add_q(Q(*args, **kwargs))
  File "C:\Users\nhanh\AppData\Local\Programs\Python\Python312\Lib\site-packages\django\db\models\sql\query.py", line 1646, in add_q
    clause, _ = self._add_q(q_object, can_reuse)
                ^^^^^^^^^^^^^^^^^^^^^^^^^^^^^^^^
  File "C:\Users\nhanh\AppData\Local\Programs\Python\Python312\Lib\site-packages\django\db\models\sql\query.py", line 1678, in _add_q
    child_clause, needed_inner = self.build_filter(
                                 ^^^^^^^^^^^^^^^^^^
  File "C:\Users\nhanh\AppData\Local\Programs\Python\Python312\Lib\site-packages\django\db\models\sql\query.py", line 1588, in build_filter
    condition = self.build_lookup(lookups, col, value)
                ^^^^^^^^^^^^^^^^^^^^^^^^^^^^^^^^^^^^^^
  File "C:\Users\nhanh\AppData\Local\Programs\Python\Python312\Lib\site-packages\django\db\models\sql\query.py", line 1415, in build_lookup
    lookup = lookup_class(lhs, rhs)
             ^^^^^^^^^^^^^^^^^^^^^^
  File "C:\Users\nhanh\AppData\Local\Programs\Python\Python312\Lib\site-packages\django\db\models\lookups.py", line 38, in __init__
    self.rhs = self.get_prep_lookup()
               ^^^^^^^^^^^^^^^^^^^^^^
  File "C:\Users\nhanh\AppData\Local\Programs\Python\Python312\Lib\site-packages\django\db\models\fields\related_lookups.py", line 112, in get_prep_lookup
    self.rhs = target_field.get_prep_value(self.rhs)
               ^^^^^^^^^^^^^^^^^^^^^^^^^^^^^^^^^^^^^
  File "C:\Users\nhanh\AppData\Local\Programs\Python\Python312\Lib\site-packages\django\db\models\fields\__init__.py", line 2750, in get_prep_value
    return self.to_python(value)
           ^^^^^^^^^^^^^^^^^^^^^
  File "C:\Users\nhanh\AppData\Local\Programs\Python\Python312\Lib\site-packages\django\db\models\fields\__init__.py", line 2768, in to_python
    raise exceptions.ValidationError(
django.core.exceptions.ValidationError: ['“AnonymousUser” is not a valid UUID.']
WARNING 2025-08-01 08:45:47,455 base 25732 15668 view's PlanActivityViewSet raised exception during schema generation; use `getattr(self, 'swagger_fake_view', False)` to detect and short-circuit this
Traceback (most recent call last):
  File "C:\Users\nhanh\AppData\Local\Programs\Python\Python312\Lib\site-packages\django\db\models\fields\__init__.py", line 2766, in to_python
    return uuid.UUID(**{input_form: value})
           ^^^^^^^^^^^^^^^^^^^^^^^^^^^^^^^^
  File "C:\Users\nhanh\AppData\Local\Programs\Python\Python312\Lib\uuid.py", line 175, in __init__
    hex = hex.replace('urn:', '').replace('uuid:', '')
          ^^^^^^^^^^^
AttributeError: 'AnonymousUser' object has no attribute 'replace'

During handling of the above exception, another exception occurred:

Traceback (most recent call last):
  File "C:\Users\nhanh\AppData\Local\Programs\Python\Python312\Lib\site-packages\drf_yasg\inspectors\base.py", line 42, in call_view_method
    return view_method()
           ^^^^^^^^^^^^^
  File "D:\Study\DoAnNganh\PlanPal\planpalapp\planpals\views.py", line 805, in get_queryset
    return PlanActivity.objects.filter(
           ^^^^^^^^^^^^^^^^^^^^^^^^^^^^
  File "C:\Users\nhanh\AppData\Local\Programs\Python\Python312\Lib\site-packages\django\db\models\manager.py", line 87, in manager_method
    return getattr(self.get_queryset(), name)(*args, **kwargs)
           ^^^^^^^^^^^^^^^^^^^^^^^^^^^^^^^^^^^^^^^^^^^^^^^^^^^
  File "C:\Users\nhanh\AppData\Local\Programs\Python\Python312\Lib\site-packages\django\db\models\query.py", line 1493, in filter
    return self._filter_or_exclude(False, args, kwargs)
           ^^^^^^^^^^^^^^^^^^^^^^^^^^^^^^^^^^^^^^^^^^^^
  File "C:\Users\nhanh\AppData\Local\Programs\Python\Python312\Lib\site-packages\django\db\models\query.py", line 1511, in _filter_or_exclude
    clone._filter_or_exclude_inplace(negate, args, kwargs)
  File "C:\Users\nhanh\AppData\Local\Programs\Python\Python312\Lib\site-packages\django\db\models\query.py", line 1518, in _filter_or_exclude_inplace
    self._query.add_q(Q(*args, **kwargs))
  File "C:\Users\nhanh\AppData\Local\Programs\Python\Python312\Lib\site-packages\django\db\models\sql\query.py", line 1646, in add_q
    clause, _ = self._add_q(q_object, can_reuse)
                ^^^^^^^^^^^^^^^^^^^^^^^^^^^^^^^^
  File "C:\Users\nhanh\AppData\Local\Programs\Python\Python312\Lib\site-packages\django\db\models\sql\query.py", line 1678, in _add_q
    child_clause, needed_inner = self.build_filter(
                                 ^^^^^^^^^^^^^^^^^^
  File "C:\Users\nhanh\AppData\Local\Programs\Python\Python312\Lib\site-packages\django\db\models\sql\query.py", line 1588, in build_filter
    condition = self.build_lookup(lookups, col, value)
                ^^^^^^^^^^^^^^^^^^^^^^^^^^^^^^^^^^^^^^
  File "C:\Users\nhanh\AppData\Local\Programs\Python\Python312\Lib\site-packages\django\db\models\sql\query.py", line 1415, in build_lookup
    lookup = lookup_class(lhs, rhs)
             ^^^^^^^^^^^^^^^^^^^^^^
  File "C:\Users\nhanh\AppData\Local\Programs\Python\Python312\Lib\site-packages\django\db\models\lookups.py", line 38, in __init__
    self.rhs = self.get_prep_lookup()
               ^^^^^^^^^^^^^^^^^^^^^^
  File "C:\Users\nhanh\AppData\Local\Programs\Python\Python312\Lib\site-packages\django\db\models\fields\related_lookups.py", line 112, in get_prep_lookup
    self.rhs = target_field.get_prep_value(self.rhs)
               ^^^^^^^^^^^^^^^^^^^^^^^^^^^^^^^^^^^^^
  File "C:\Users\nhanh\AppData\Local\Programs\Python\Python312\Lib\site-packages\django\db\models\fields\__init__.py", line 2750, in get_prep_value
    return self.to_python(value)
           ^^^^^^^^^^^^^^^^^^^^^
  File "C:\Users\nhanh\AppData\Local\Programs\Python\Python312\Lib\site-packages\django\db\models\fields\__init__.py", line 2768, in to_python
    raise exceptions.ValidationError(
django.core.exceptions.ValidationError: ['“AnonymousUser” is not a valid UUID.']
INFO 2025-08-01 09:14:50,063 autoreload 32184 41460 Watching for file changes with StatReloader
WARNING 2025-08-01 09:21:33,223 log 32184 35824 Unauthorized: /auth/logout/
WARNING 2025-08-01 09:25:29,771 log 32184 41928 Unauthorized: /auth/logout/
WARNING 2025-08-01 09:30:16,654 log 32184 45812 Unauthorized: /auth/logout/
INFO 2025-08-01 09:34:06,631 autoreload 32184 41460 D:\Study\DoAnNganh\PlanPal\planpalapp\planpals\views.py changed, reloading.
INFO 2025-08-01 09:34:07,723 autoreload 43164 41856 Watching for file changes with StatReloader
INFO 2025-08-01 09:35:13,494 autoreload 43164 41856 D:\Study\DoAnNganh\PlanPal\planpalapp\planpals\views.py changed, reloading.
INFO 2025-08-01 09:35:14,855 autoreload 45812 37784 Watching for file changes with StatReloader
INFO 2025-08-01 09:37:21,426 autoreload 45812 37784 D:\Study\DoAnNganh\PlanPal\planpalapp\planpals\views.py changed, reloading.
INFO 2025-08-01 09:37:22,828 autoreload 29292 38328 Watching for file changes with StatReloader
INFO 2025-08-01 09:41:05,473 autoreload 29292 38328 D:\Study\DoAnNganh\PlanPal\planpalapp\planpals\views.py changed, reloading.
INFO 2025-08-01 09:41:06,818 autoreload 42880 37116 Watching for file changes with StatReloader
INFO 2025-08-01 09:41:20,264 autoreload 42880 37116 D:\Study\DoAnNganh\PlanPal\planpalapp\planpals\views.py changed, reloading.
INFO 2025-08-01 09:41:21,498 autoreload 44468 47004 Watching for file changes with StatReloader
INFO 2025-08-01 09:43:04,211 autoreload 44468 47004 D:\Study\DoAnNganh\PlanPal\planpalapp\planpals\views.py changed, reloading.
INFO 2025-08-01 09:43:05,396 autoreload 42744 46768 Watching for file changes with StatReloader
INFO 2025-08-01 09:44:14,496 autoreload 42744 46768 D:\Study\DoAnNganh\PlanPal\planpalapp\planpals\views.py changed, reloading.
INFO 2025-08-01 09:44:15,945 autoreload 46360 47060 Watching for file changes with StatReloader
INFO 2025-08-01 09:44:36,835 autoreload 46360 47060 D:\Study\DoAnNganh\PlanPal\planpalapp\planpals\views.py changed, reloading.
INFO 2025-08-01 09:44:38,030 autoreload 46356 46280 Watching for file changes with StatReloader
INFO 2025-08-01 09:44:49,988 autoreload 46356 46280 D:\Study\DoAnNganh\PlanPal\planpalapp\planpals\views.py changed, reloading.
INFO 2025-08-01 09:44:51,813 autoreload 276 39112 Watching for file changes with StatReloader
INFO 2025-08-01 09:44:54,923 autoreload 276 39112 D:\Study\DoAnNganh\PlanPal\planpalapp\planpals\views.py changed, reloading.
INFO 2025-08-01 09:44:56,643 autoreload 48504 48508 Watching for file changes with StatReloader
INFO 2025-08-01 09:45:04,675 autoreload 48504 48508 D:\Study\DoAnNganh\PlanPal\planpalapp\planpals\views.py changed, reloading.
INFO 2025-08-01 09:45:06,082 autoreload 48628 48796 Watching for file changes with StatReloader
INFO 2025-08-01 09:45:09,633 autoreload 48628 48796 D:\Study\DoAnNganh\PlanPal\planpalapp\planpals\views.py changed, reloading.
INFO 2025-08-01 09:45:10,643 autoreload 48456 48464 Watching for file changes with StatReloader
INFO 2025-08-01 09:45:14,442 autoreload 48456 48464 D:\Study\DoAnNganh\PlanPal\planpalapp\planpals\views.py changed, reloading.
INFO 2025-08-01 09:45:15,862 autoreload 48756 48816 Watching for file changes with StatReloader
INFO 2025-08-01 09:45:26,192 autoreload 48756 48816 D:\Study\DoAnNganh\PlanPal\planpalapp\planpals\views.py changed, reloading.
INFO 2025-08-01 09:45:27,549 autoreload 26856 48588 Watching for file changes with StatReloader
INFO 2025-08-01 09:45:31,761 autoreload 26856 48588 D:\Study\DoAnNganh\PlanPal\planpalapp\planpals\views.py changed, reloading.
INFO 2025-08-01 09:45:33,414 autoreload 21536 47064 Watching for file changes with StatReloader
INFO 2025-08-01 09:45:35,993 autoreload 21536 47064 D:\Study\DoAnNganh\PlanPal\planpalapp\planpals\views.py changed, reloading.
INFO 2025-08-01 09:45:37,527 autoreload 49004 46496 Watching for file changes with StatReloader
